Workbook

Sheet Данные
A1: ФИО менеджера | B1: ФИО клиента | C1: Дата сделки | D1: Сумма сделки | E1: NPS
A2: Фролов Сергей Викторович | B2: Орлова Анна Владимировна | C2: 2023-09-01 | D2: 62110 | E2: 5
A3: Кузнецов Дмитрий Львович | B3: Иванова Анна Геннадьевна | C3: 2023-09-04 | D3: 73955 | E3: 7
A4: Иванова Анна Сергеевна | B4: Егорова Татьяна Ильинична | C4: 2023-09-04 | D4: 60135 | E4: 8
A5: Громова Мария Ильинична | B5: Сидоров Алексей Кириллович | C5: 2023-09-04 | D5: 59782 | E5: 8
A6: Сидорова Елена Васильевна | B6: Иванов Матвей Юрьевич | C6: 2023-09-04 | D6: 71041 | E6: 0
A7: Новикова Ольга Петровна | B7: Васильев Дмитрий Алексеевич | C7: 2023-09-04 | D7: 62764 | E7: 7
A8: Кузнецов Дмитрий Львович | B8: Орлова Людмила Артемовна | C8: 2023-09-04 | D8: 97781 | E8: 10
A9: Иванова Анна Сергеевна | B9: Попова Ксения Никитична | C9: 2023-09-04 | D9: 32384 | E9: 8
A10: Яковлев Артем Игоревич | B10: Кузнецов Дмитрий Андреевич | C10: 2023-09-05 | D10: 74878 | E10: 4
A11: Ткаченко Андрей Олегович | B11: Павлов Кирилл Иванович | C11: 2023-09-05 | D11: 72619 | E11: 7
A12: Новикова Ольга Петровна | B12: Егоров Владимир Артемович | C12: 2023-09-06 | D12: 41496 | E12: 7
A13: Петров Владимир Кириллович | B13: Кузнецова Юлия Павловна | C13: 2023-09-06 | D13: 84622 | E13: 7
... A1001: Фролов Сергей Викторович | B1001: Федоров Алексей Павлович | C1001: 2024-09-02 | D1001: 76169 | E1001: 7

Sheet результат
A1: ФИО студента: | B1: Сидоров Сидр Сидорович
A2: Задача 1 | B2: Для каждого менеджера найти метрики: | G2: ФИО Менеджера (по алфавиту) | H2: Клиенты | I2: Сумма | J2: Длительность, дни | K2: NPS
B3: - количество клиентов - (столбец H) | F3: 1 | G3: Белов Алексей Константинович | H3: =COUNTIF('Задание1'!D:D,G3) -> 66 | I3: =SUMIF('Данные'!A:A,G3,'Данные'!D:D) -> 4641369 | J3: =VLOOKUP(G3,'Задание1.1'!A:E,5,0) -> 315 | K3: =(COUNTIFS('Данные'!A:A,G3,'Данные'!E:E,">=9")-COUNTIFS('Данные'!A:A,G3,'Данные'!E:E,"<=6"))/COUNTIFS('Данные'!A:A,G3,'Данные'!E:E,">=0") -> -0.24691358
B4: - сумма проектов - (столбец I) | F4: 2 | G4: Громова Мария Ильинична | H4: =COUNTIF('Задание1'!D:D,G4) -> 68 | I4: =SUMIF('Данные'!A:A,G4,'Данные'!D:D) -> 4039577 | J4: =VLOOKUP(G4,'Задание1.1'!A:E,5,0) -> 322 | K4: =(COUNTIFS('Данные'!A:A,G4,'Данные'!E:E,">=9")-COUNTIFS('Данные'!A:A,G4,'Данные'!E:E,"<=6"))/COUNTIFS('Данные'!A:A,G4,'Данные'!E:E,">=0") -> -0.35064935
B5: - длительность работы с клиентом от первой сделки до последней - (столбец J) | F5: 3 | G5: Иванова Анна Сергеевна | H5: =COUNTIF('Задание1'!D:D,G5) -> 63 | I5: =SUMIF('Данные'!A:A,G5,'Данные'!D:D) -> 4377973 | J5: =VLOOKUP(G5,'Задание1.1'!A:E,5,0) -> 280 | K5: =(COUNTIFS('Данные'!A:A,G5,'Данные'!E:E,">=9")-COUNTIFS('Данные'!A:A,G5,'Данные'!E:E,"<=6"))/COUNTIFS('Данные'!A:A,G5,'Данные'!E:E,">=0") -> -0.27272727
B6: (для каждого менеджера определить самого долгого клиента в днях | F6: 4 | G6: Кузнецов Дмитрий Львович | H6: =COUNTIF('Задание1'!D:D,G6) -> 78 | I6: =SUMIF('Данные'!A:A,G6,'Данные'!D:D) -> 5075530 | J6: =VLOOKUP(G6,'Задание1.1'!A:E,5,0) -> 349 | K6: =(COUNTIFS('Данные'!A:A,G6,'Данные'!E:E,">=9")-COUNTIFS('Данные'!A:A,G6,'Данные'!E:E,"<=6"))/COUNTIFS('Данные'!A:A,G6,'Данные'!E:E,">=0") -> -0.21052632
B7: от даты заключения первого проекта до даты заключения последнего проекта). | F7: 5 | G7: Новикова Ольга Петровна | H7: =COUNTIF('Задание1'!D:D,G7) -> 74 | I7: =SUMIF('Данные'!A:A,G7,'Данные'!D:D) -> 5011933 | J7: =VLOOKUP(G7,'Задание1.1'!A:E,5,0) -> 295 | K7: =(COUNTIFS('Данные'!A:A,G7,'Данные'!E:E,">=9")-COUNTIFS('Данные'!A:A,G7,'Данные'!E:E,"<=6"))/COUNTIFS('Данные'!A:A,G7,'Данные'!E:E,">=0") -> -0.25263158
B8: - NPS по всем проектам - (столбец K) | F8: 6 | G8: Орлов Павел Денисович | H8: =COUNTIF('Задание1'!D:D,G8) -> 67 | I8: =SUMIF('Данные'!A:A,G8,'Данные'!D:D) -> 4999561 | J8: =VLOOKUP(G8,'Задание1.1'!A:E,5,0) -> 199 | K8: =(COUNTIFS('Данные'!A:A,G8,'Данные'!E:E,">=9")-COUNTIFS('Данные'!A:A,G8,'Данные'!E:E,"<=6"))/COUNTIFS('Данные'!A:A,G8,'Данные'!E:E,">=0") -> -0.34939759
F9: 7 | G9: Петров Владимир Кириллович | H9: =COUNTIF('Задание1'!D:D,G9) -> 68 | I9: =SUMIF('Данные'!A:A,G9,'Данные'!D:D) -> 4533971 | J9: =VLOOKUP(G9,'Задание1.1'!A:E,5,0) -> 325 | K9: =(COUNTIFS('Данные'!A:A,G9,'Данные'!E:E,">=9")-COUNTIFS('Данные'!A:A,G9,'Данные'!E:E,"<=6"))/COUNTIFS('Данные'!A:A,G9,'Данные'!E:E,">=0") -> -0.2962963
F10: 8 | G10: Семенова Ирина Валерьевна | H10: =COUNTIF('Задание1'!D:D,G10) -> 64 | I10: =SUMIF('Данные'!A:A,G10,'Данные'!D:D) -> 4264531 | J10: =VLOOKUP(G10,'Задание1.1'!A:E,5,0) -> 315 | K10: =(COUNTIFS('Данные'!A:A,G10,'Данные'!E:E,">=9")-COUNTIFS('Данные'!A:A,G10,'Данные'!E:E,"<=6"))/COUNTIFS('Данные'!A:A,G10,'Данные'!E:E,">=0") -> -0.38461538
F11: 9 | G11: Сидорова Елена Васильевна | H11: =COUNTIF('Задание1'!D:D,G11) -> 76 | I11: =SUMIF('Данные'!A:A,G11,'Данные'!D:D) -> 4895374 | J11: =VLOOKUP(G11,'Задание1.1'!A:E,5,0) -> 268 | K11: =(COUNTIFS('Данные'!A:A,G11,'Данные'!E:E,">=9")-COUNTIFS('Данные'!A:A,G11,'Данные'!E:E,"<=6"))/COUNTIFS('Данные'!A:A,G11,'Данные'!E:E,">=0") -> -0.30769231
B12: Определить самого эффективного менеджера: | F12: 10 | G12: Ткаченко Андрей Олегович | H12: =COUNTIF('Задание1'!D:D,G12) -> 68 | I12: =SUMIF('Данные'!A:A,G12,'Данные'!D:D) -> 4412645 | J12: =VLOOKUP(G12,'Задание1.1'!A:E,5,0) -> 293 | K12: =(COUNTIFS('Данные'!A:A,G12,'Данные'!E:E,">=9")-COUNTIFS('Данные'!A:A,G12,'Данные'!E:E,"<=6"))/COUNTIFS('Данные'!A:A,G12,'Данные'!E:E,">=0") -> -0.23170732
A13: по количеству клиентов | B13: =INDEX(G3:G14,MATCH(MAX(H3:H14),H3:H14,0)) -> Кузнецов Дмитрий Львович | F13: 11 | G13: Фролов Сергей Викторович | H13: =COUNTIF('Задание1'!D:D,G13) -> 73 | I13: =SUMIF('Данные'!A:A,G13,'Данные'!D:D) -> 4929107 | J13: =VLOOKUP(G13,'Задание1.1'!A:E,5,0) -> 237 | K13: =(COUNTIFS('Данные'!A:A,G13,'Данные'!E:E,">=9")-COUNTIFS('Данные'!A:A,G13,'Данные'!E:E,"<=6"))/COUNTIFS('Данные'!A:A,G13,'Данные'!E:E,">=0") -> -0.37209302
F14: 12 | G14: Яковлев Артем Игоревич | H14: =COUNTIF('Задание1'!D:D,G14) -> 62 | I14: =SUMIF('Данные'!A:A,G14,'Данные'!D:D) -> 4409450 | J14: =VLOOKUP(G14,'Задание1.1'!A:E,5,0) -> 246 | K14: =(COUNTIFS('Данные'!A:A,G14,'Данные'!E:E,">=9")-COUNTIFS('Данные'!A:A,G14,'Данные'!E:E,"<=6"))/COUNTIFS('Данные'!A:A,G14,'Данные'!E:E,">=0") -> -0.37837838
A15: по сумме проектов | B15: =INDEX(G3:G14,MATCH(MAX(I3:I14),I3:I14,0)) -> Кузнецов Дмитрий Львович
A17: по длительности работы | B17: =INDEX(G3:G14,MATCH(MAX(J3:J14),J3:J14,0)) -> Кузнецов Дмитрий Львович
A19: NPS | B19: =INDEX(G3:G14,MATCH(MAX(K3:K14),K3:K14,0)) -> Кузнецов Дмитрий Львович
A23: Задача 2 | B23: Оценить клиентов | G23: ТОП 10 клиентов по продажам
B24: - доходности (вывести топ 10 клиентов) | G24: ФИО | H24: Проекты | I24: Сумма
B25: - не переходил к другим менеджерам - вывести первых 10 по алфавиту | F25: 1 | G25: Морозова Светлана Сергеевна | H25: 9 | I25: 676125
B26: - по длительности (сколько месяцев суммарно обслуживался клиент) | F26: 2 | G26: Николаев Артур Артемович | H26: 9 | I26: 627885
F27: 3 | G27: Попова Полина Романовна | H27: 11 | I27: 620837
F28: 4 | G28: Алексеева Наталья Андреевна | H28: 9 | I28: 620614
F29: 5 | G29: Орлова Анна Владимировна | H29: 9 | I29: 616547
F30: 6 | G30: Николаева Александра Кирилловна | H30: 8 | I30: 579536
F31: 7 | G31: Иванов Павел Сергеевич | H31: 11 | I31: 576582
F32: 8 | G32: Козлов Дмитрий Сергеевич | H32: 11 | I32: 572727
F33: 9 | G33: Егоров Никита Станиславович | H33: 10 | I33: 563986
F34: 10 | G34: Сидорова Екатерина Романовна | H34: 9 | I34: 544040
G37: 10 клиентов, которые обслуживались у одного менеджера (в алфавитном порядке)
G38: ФИО | H38: Проекты | I38: Сумма
F39: 1 | G39: Волкова Виктория Викторовна | H39: 1 | I39: 50052
F40: 2 | G40: Иванов Михаил Никитич | H40: 1 | I40: 70414
F41: 3 | G41: Морозова Юлия Егоровна | H41: 1 | I41: 24770
F42: 4 | G42: Николаев Егор Романович | H42: 1 | I42: 58326
F43: 5 | G43: Смирнов Дмитрий Павлович | H43: 2 | I43: 154284
F44: 6 | G44: Смирнов Сергей Андреевич | H44: 1 | I44: 13819
F45: 7
F46: 8
F47: 9
...

Sheet Задание1
A1: ФИО менеджера | D1: ФИО менеджера | E1: ФИО клиента | F1: первый проект | G1: последний проект | H1: Дни | J1: М+К | K1: ФИО менеджера | L1: ФИО клиента | M1: Дата сделки | N1: Менедж+Клиент | O1: ФИО менеджера | P1: ФИО клиента | Q1: Дата сделки
A2: Белов Алексей Константинович | D2: Белов Алексей Константинович | E2: Алексеев Иван Иванович | F2: =VLOOKUP(D2&E2,J:M,4,0) -> 2023-09-20 | G2: =VLOOKUP(D2&E2,N:Q,4,0) -> 2024-07-31 | H2: =G2-F2 -> 315 | J2: =K2&L2 -> Фролов Сергей ВикторовичОрлова Анна Владимировна | K2: Фролов Сергей Викторович | L2: Орлова Анна Владимировна | M2: 2023-09-01 | N2: =O2&P2 -> Фролов Сергей ВикторовичФедоров Алексей Павлович | O2: Фролов Сергей Викторович | P2: Федоров Алексей Павлович | Q2: 2024-09-02
A3: Громова Мария Ильинична | D3: Белов Алексей Константинович | E3: Алексеева Анна Олеговна | F3: =VLOOKUP(D3&E3,J:M,4,0) -> 2024-03-19 | G3: =VLOOKUP(D3&E3,N:Q,4,0) -> 2024-05-29 | H3: =G3-F3 -> 71 | J3: =K3&L3 -> Кузнецов Дмитрий ЛьвовичИванова Анна Геннадьевна | K3: Кузнецов Дмитрий Львович | L3: Иванова Анна Геннадьевна | M3: 2023-09-04 | N3: =O3&P3 -> Новикова Ольга ПетровнаВасильева Анна Ильинична | O3: Новикова Ольга Петровна | P3: Васильева Анна Ильинична | Q3: 2024-08-30
A4: Иванова Анна Сергеевна | D4: Белов Алексей Константинович | E4: Алексеева Ирина Андреевна | F4: =VLOOKUP(D4&E4,J:M,4,0) -> 2024-04-18 | G4: =VLOOKUP(D4&E4,N:Q,4,0) -> 2024-04-18 | H4: =G4-F4 -> 0 | J4: =K4&L4 -> Иванова Анна СергеевнаЕгорова Татьяна Ильинична | K4: Иванова Анна Сергеевна | L4: Егорова Татьяна Ильинична | M4: 2023-09-04 | N4: =O4&P4 -> Орлов Павел ДенисовичНиколаева Дарья Юрьевна | O4: Орлов Павел Денисович | P4: Николаева Дарья Юрьевна | Q4: 2024-08-30
A5: Кузнецов Дмитрий Львович | D5: Белов Алексей Константинович | E5: Алексеева Наталья Андреевна | F5: =VLOOKUP(D5&E5,J:M,4,0) -> 2024-02-05 | G5: =VLOOKUP(D5&E5,N:Q,4,0) -> 2024-04-04 | H5: =G5-F5 -> 59 | J5: =K5&L5 -> Громова Мария ИльиничнаСидоров Алексей Кириллович | K5: Громова Мария Ильинична | L5: Сидоров Алексей Кириллович | M5: 2023-09-04 | N5: =O5&P5 -> Ткаченко Андрей ОлеговичСмирнов Артем Егорович | O5: Ткаченко Андрей Олегович | P5: Смирнов Артем Егорович | Q5: 2024-08-30
A6: Новикова Ольга Петровна | D6: Белов Алексей Константинович | E6: Васильев Александр Павлович | F6: =VLOOKUP(D6&E6,J:M,4,0) -> 2024-05-15 | G6: =VLOOKUP(D6&E6,N:Q,4,0) -> 2024-05-15 | H6: =G6-F6 -> 0 | J6: =K6&L6 -> Сидорова Елена ВасильевнаИванов Матвей Юрьевич | K6: Сидорова Елена Васильевна | L6: Иванов Матвей Юрьевич | M6: 2023-09-04 | N6: =O6&P6 -> Ткаченко Андрей ОлеговичСидорова Екатерина Романовна | O6: Ткаченко Андрей Олегович | P6: Сидорова Екатерина Романовна | Q6: 2024-08-30
A7: Орлов Павел Денисович | D7: Белов Алексей Константинович | E7: Васильев Дмитрий Алексеевич | F7: =VLOOKUP(D7&E7,J:M,4,0) -> 2024-05-30 | G7: =VLOOKUP(D7&E7,N:Q,4,0) -> 2024-05-30 | H7: =G7-F7 -> 0 | J7: =K7&L7 -> Новикова Ольга ПетровнаВасильев Дмитрий Алексеевич | K7: Новикова Ольга Петровна | L7: Васильев Дмитрий Алексеевич | M7: 2023-09-04 | N7: =O7&P7 -> Кузнецов Дмитрий ЛьвовичНиколаев Артем Александрович | O7: Кузнецов Дмитрий Львович | P7: Николаев Артем Александрович | Q7: 2024-08-29
A8: Петров Владимир Кириллович | D8: Белов Алексей Константинович | E8: Васильев Кирилл Иванович | F8: =VLOOKUP(D8&E8,J:M,4,0) -> 2024-04-15 | G8: =VLOOKUP(D8&E8,N:Q,4,0) -> 2024-04-15 | H8: =G8-F8 -> 0 | J8: =K8&L8 -> Кузнецов Дмитрий ЛьвовичОрлова Людмила Артемовна | K8: Кузнецов Дмитрий Львович | L8: Орлова Людмила Артемовна | M8: 2023-09-04 | N8: =O8&P8 -> Семенова Ирина ВалерьевнаВасильева Ирина Артемовна | O8: Семенова Ирина Валерьевна | P8: Васильева Ирина Артемовна | Q8: 2024-08-29
A9: Семенова Ирина Валерьевна | D9: Белов Алексей Константинович | E9: Васильева Юлия Геннадьевна | F9: =VLOOKUP(D9&E9,J:M,4,0) -> 2023-09-12 | G9: =VLOOKUP(D9&E9,N:Q,4,0) -> 2023-09-12 | H9: =G9-F9 -> 0 | J9: =K9&L9 -> Иванова Анна СергеевнаПопова Ксения Никитична | K9: Иванова Анна Сергеевна | L9: Попова Ксения Никитична | M9: 2023-09-04 | N9: =O9&P9 -> Кузнецов Дмитрий ЛьвовичСтепанова Анна Олеговна | O9: Кузнецов Дмитрий Львович | P9: Степанова Анна Олеговна | Q9: 2024-08-29
A10: Сидорова Елена Васильевна | D10: Белов Алексей Константинович | E10: Волков Константин Александрович | F10: =VLOOKUP(D10&E10,J:M,4,0) -> 2024-04-22 | G10: =VLOOKUP(D10&E10,N:Q,4,0) -> 2024-06-07 | H10: =G10-F10 -> 46 | J10: =K10&L10 -> Яковлев Артем ИгоревичКузнецов Дмитрий Андреевич | K10: Яковлев Артем Игоревич | L10: Кузнецов Дмитрий Андреевич | M10: 2023-09-05 | N10: =O10&P10 -> Яковлев Артем ИгоревичФедорова Екатерина Сергеевна | O10: Яковлев Артем Игоревич | P10: Федорова Екатерина Сергеевна | Q10: 2024-08-28
A11: Ткаченко Андрей Олегович | D11: Белов Алексей Константинович | E11: Волков Константин Дмитриевич | F11: =VLOOKUP(D11&E11,J:M,4,0) -> 2023-12-25 | G11: =VLOOKUP(D11&E11,N:Q,4,0) -> 2023-12-25 | H11: =G11-F11 -> 0 | J11: =K11&L11 -> Ткаченко Андрей ОлеговичПавлов Кирилл Иванович | K11: Ткаченко Андрей Олегович | L11: Павлов Кирилл Иванович | M11: 2023-09-05 | N11: =O11&P11 -> Орлов Павел ДенисовичВасильев Алексей Андреевич | O11: Орлов Павел Денисович | P11: Васильев Алексей Андреевич | Q11: 2024-08-28
A12: Фролов Сергей Викторович | D12: Белов Алексей Константинович | E12: Волков Матвей Кириллович | F12: =VLOOKUP(D12&E12,J:M,4,0) -> 2024-02-23 | G12: =VLOOKUP(D12&E12,N:Q,4,0) -> 2024-02-23 | H12: =G12-F12 -> 0 | J12: =K12&L12 -> Новикова Ольга ПетровнаЕгоров Владимир Артемович | K12: Новикова Ольга Петровна | L12: Егоров Владимир Артемович | M12: 2023-09-06 | N12: =O12&P12 -> Семенова Ирина ВалерьевнаАлексеева Наталья Андреевна | O12: Семенова Ирина Валерьевна | P12: Алексеева Наталья Андреевна | Q12: 2024-08-27
A13: Яковлев Артем Игоревич | D13: Белов Алексей Константинович | E13: Волкова Анна Кирилловна | F13: =VLOOKUP(D13&E13,J:M,4,0) -> 2024-04-22 | G13: =VLOOKUP(D13&E13,N:Q,4,0) -> 2024-04-22 | H13: =G13-F13 -> 0 | J13: =K13&L13 -> Петров Владимир КирилловичКузнецова Юлия Павловна | K13: Петров Владимир Кириллович | L13: Кузнецова Юлия Павловна | M13: 2023-09-06 | N13: =O13&P13 -> Белов Алексей КонстантиновичИванов Михаил Никитич | O13: Белов Алексей Константинович | P13: Иванов Михаил Никитич | Q13: 2024-08-27
D14: Белов Алексей Константинович | E14: Волкова Ирина Никитична | F14: =VLOOKUP(D14&E14,J:M,4,0) -> 2023-11-23 | G14: =VLOOKUP(D14&E14,N:Q,4,0) -> 2023-11-23 | H14: =G14-F14 -> 0 | J14: =K14&L14 -> Иванова Анна СергеевнаСеменов Сергей Викторович | K14: Иванова Анна Сергеевна | L14: Семенов Сергей Викторович | M14: 2023-09-06 | N14: =O14&P14 -> Новикова Ольга ПетровнаСтепанов Матвей Михайлович | O14: Новикова Ольга Петровна | P14: Степанов Матвей Михайлович | Q14: 2024-08-27
D15: Белов Алексей Константинович | E15: Волкова Мария Ильинична | F15: =VLOOKUP(D15&E15,J:M,4,0) -> 2024-05-20 | G15: =VLOOKUP(D15&E15,N:Q,4,0) -> 2024-05-20 | H15: =G15-F15 -> 0 | J15: =K15&L15 -> Кузнецов Дмитрий ЛьвовичСмирнова Алиса Артемовна | K15: Кузнецов Дмитрий Львович | L15: Смирнова Алиса Артемовна | M15: 2023-09-07 | N15: =O15&P15 -> Сидорова Елена ВасильевнаСидоров Сергей Егорович | O15: Сидорова Елена Васильевна | P15: Сидоров Сергей Егорович | Q15: 2024-08-27
D16: Белов Алексей Константинович | E16: Егоров Владимир Артемович | F16: =VLOOKUP(D16&E16,J:M,4,0) -> 2024-04-19 | G16: =VLOOKUP(D16&E16,N:Q,4,0) -> 2024-04-19 | H16: =G16-F16 -> 0 | J16: =K16&L16 -> Новикова Ольга ПетровнаИванова Виктория Михайловна | K16: Новикова Ольга Петровна | L16: Иванова Виктория Михайловна | M16: 2023-09-08 | N16: =O16&P16 -> Ткаченко Андрей ОлеговичОрлова Людмила Артемовна | O16: Ткаченко Андрей Олегович | P16: Орлова Людмила Артемовна | Q16: 2024-08-26
D17: Белов Алексей Константинович | E17: Егорова Ирина Кирилловна | F17: =VLOOKUP(D17&E17,J:M,4,0) -> 2024-03-28 | G17: =VLOOKUP(D17&E17,N:Q,4,0) -> 2024-07-22 | H17: =G17-F17 -> 116 | J17: =K17&L17 -> Ткаченко Андрей ОлеговичНовикова Анна Ильинична | K17: Ткаченко Андрей Олегович | L17: Новикова Анна Ильинична | M17: 2023-09-08 | N17: =O17&P17 -> Орлов Павел ДенисовичСидоров Сергей Егорович | O17: Орлов Павел Денисович | P17: Сидоров Сергей Егорович | Q17: 2024-08-26
D18: Белов Алексей Константинович | E18: Егорова Ольга Юрьевна | F18: =VLOOKUP(D18&E18,J:M,4,0) -> 2024-01-08 | G18: =VLOOKUP(D18&E18,N:Q,4,0) -> 2024-01-08 | H18: =G18-F18 -> 0 | J18: =K18&L18 -> Петров Владимир КирилловичКузнецов Дмитрий Андреевич | K18: Петров Владимир Кириллович | L18: Кузнецов Дмитрий Андреевич | M18: 2023-09-11 | N18: =O18&P18 -> Кузнецов Дмитрий ЛьвовичФедорова Анна Михайловна | O18: Кузнецов Дмитрий Львович | P18: Федорова Анна Михайловна | Q18: 2024-08-26
D19: Белов Алексей Константинович | E19: Егорова Татьяна Ильинична | F19: =VLOOKUP(D19&E19,J:M,4,0) -> 2024-04-23 | G19: =VLOOKUP(D19&E19,N:Q,4,0) -> 2024-04-23 | H19: =G19-F19 -> 0 | J19: =K19&L19 -> Петров Владимир КирилловичНиколаев Дмитрий Павлович | K19: Петров Владимир Кириллович | L19: Николаев Дмитрий Павлович | M19: 2023-09-11 | N19: =O19&P19 -> Кузнецов Дмитрий ЛьвовичАлексеева Ирина Андреевна | O19: Кузнецов Дмитрий Львович | P19: Алексеева Ирина Андреевна | Q19: 2024-08-26
D20: Белов Алексей Константинович | E20: Иванов Матвей Юрьевич | F20: =VLOOKUP(D20&E20,J:M,4,0) -> 2024-01-29 | G20: =VLOOKUP(D20&E20,N:Q,4,0) -> 2024-01-29 | H20: =G20-F20 -> 0 | J20: =K20&L20 -> Сидорова Елена ВасильевнаИванова Валерия Алексеевна | K20: Сидорова Елена Васильевна | L20: Иванова Валерия Алексеевна | M20: 2023-09-11 | N20: =O20&P20 -> Новикова Ольга ПетровнаФедорова Анна Кирилловна | O20: Новикова Ольга Петровна | P20: Федорова Анна Кирилловна | Q20: 2024-08-26
D21: Белов Алексей Константинович | E21: Иванов Михаил Никитич | F21: =VLOOKUP(D21&E21,J:M,4,0) -> 2024-08-27 | G21: =VLOOKUP(D21&E21,N:Q,4,0) -> 2024-08-27 | H21: =G21-F21 -> 0 | J21: =K21&L21 -> Яковлев Артем ИгоревичМорозов Матвей Романович | K21: Яковлев Артем Игоревич | L21: Морозов Матвей Романович | M21: 2023-09-11 | N21: =O21&P21 -> Кузнецов Дмитрий ЛьвовичАлексеева София Андреевна | O21: Кузнецов Дмитрий Львович | P21: Алексеева София Андреевна | Q21: 2024-08-26
D22: Белов Алексей Константинович | E22: Иванов Павел Павлович | F22: =VLOOKUP(D22&E22,J:M,4,0) -> 2024-01-18 | G22: =VLOOKUP(D22&E22,N:Q,4,0) -> 2024-01-18 | H22: =G22-F22 -> 0 | J22: =K22&L22 -> Кузнецов Дмитрий ЛьвовичКузнецова София Александровна | K22: Кузнецов Дмитрий Львович | L22: Кузнецова София Александровна | M22: 2023-09-11 | N22: =O22&P22 -> Иванова Анна СергеевнаСмирнов Константин Егорович | O22: Иванова Анна Сергеевна | P22: Смирнов Константин Егорович | Q22: 2024-08-26
D23: Белов Алексей Константинович | E23: Иванова Ксения Александровна | F23: =VLOOKUP(D23&E23,J:M,4,0) -> 2024-05-03 | G23: =VLOOKUP(D23&E23,N:Q,4,0) -> 2024-05-03 | H23: =G23-F23 -> 0 | J23: =K23&L23 -> Сидорова Елена ВасильевнаОрлова Дарья Станиславовна | K23: Сидорова Елена Васильевна | L23: Орлова Дарья Станиславовна | M23: 2023-09-11 | N23: =O23&P23 -> Кузнецов Дмитрий ЛьвовичИванова Валерия Алексеевна | O23: Кузнецов Дмитрий Львович | P23: Иванова Валерия Алексеевна | Q23: 2024-08-26
D24: Белов Алексей Константинович | E24: Козлова София Олеговна | F24: =VLOOKUP(D24&E24,J:M,4,0) -> 2024-05-03 | G24: =VLOOKUP(D24&E24,N:Q,4,0) -> 2024-07-10 | H24: =G24-F24 -> 68 | J24: =K24&L24 -> Громова Мария ИльиничнаАлексеева Наталья Андреевна | K24: Громова Мария Ильинична | L24: Алексеева Наталья Андреевна | M24: 2023-09-11 | N24: =O24&P24 -> Ткаченко Андрей ОлеговичСидорова Екатерина Романовна | O24: Ткаченко Андрей Олегович | P24: Сидорова Екатерина Романовна | Q24: 2024-08-23
D25: Белов Алексей Константинович | E25: Кузнецов Дмитрий Андреевич | F25: =VLOOKUP(D25&E25,J:M,4,0) -> 2023-09-19 | G25: =VLOOKUP(D25&E25,N:Q,4,0) -> 2023-09-20 | H25: =G25-F25 -> 1 | J25: =K25&L25 -> Фролов Сергей ВикторовичСидоров Алексей Кириллович | K25: Фролов Сергей Викторович | L25: Сидоров Алексей Кириллович | M25: 2023-09-11 | N25: =O25&P25 -> Новикова Ольга ПетровнаНиколаев Артем Александрович | O25: Новикова Ольга Петровна | P25: Николаев Артем Александрович | Q25: 2024-08-23
... D828: Яковлев Артем Игоревич | E828: Федорова Мария Ивановна | F828: =VLOOKUP(D828&E828,J:M,4,0) -> 2024-06-03 | G828: =VLOOKUP(D828&E828,N:Q,4,0) -> 2024-06-03 | H828: =G828-F828 -> 0 | J828: =K828&L828 -> Фролов Сергей ВикторовичИванова Анна Геннадьевна | K828: Фролов Сергей Викторович | L828: Иванова Анна Геннадьевна | M828: 2024-06-24 | N828: =O828&P828 -> Кузнецов Дмитрий ЛьвовичОрлова Людмила Артемовна | O828: Кузнецов Дмитрий Львович | P828: Орлова Людмила Артемовна | Q828: 2023-11-09
J829: =K829&L829 -> Сидорова Елена ВасильевнаМорозова Екатерина Ивановна | K829: Сидорова Елена Васильевна | L829: Морозова Екатерина Ивановна | M829: 2024-06-24 | N829: =O829&P829 -> Фролов Сергей ВикторовичИванов Павел Сергеевич | O829: Фролов Сергей Викторович | P829: Иванов Павел Сергеевич | Q829: 2023-11-09
J830: =K830&L830 -> Сидорова Елена ВасильевнаНиколаева Александра Александровна | K830: Сидорова Елена Васильевна | L830: Николаева Александра Александровна | M830: 2024-06-24 | N830: =O830&P830 -> Ткаченко Андрей ОлеговичОрлова Дарья Станиславовна | O830: Ткаченко Андрей Олегович | P830: Орлова Дарья Станиславовна | Q830: 2023-11-09
J831: =K831&L831 -> Ткаченко Андрей ОлеговичПопова Полина Романовна | K831: Ткаченко Андрей Олегович | L831: Попова Полина Романовна | M831: 2024-06-24 | N831: =O831&P831 -> Яковлев Артем ИгоревичСтепанов Матвей Михайлович | O831: Яковлев Артем Игоревич | P831: Степанов Матвей Михайлович | Q831: 2023-11-07
J832: =K832&L832 -> Иванова Анна СергеевнаОрлова Анна Владимировна | K832: Иванова Анна Сергеевна | L832: Орлова Анна Владимировна | M832: 2024-06-24 | N832: =O832&P832 -> Громова Мария ИльиничнаСидорова Ольга Олеговна | O832: Громова Мария Ильинична | P832: Сидорова Ольга Олеговна | Q832: 2023-11-07
J833: =K833&L833 -> Яковлев Артем ИгоревичЕгоров Андрей Дмитриевич | K833: Яковлев Артем Игоревич | L833: Егоров Андрей Дмитриевич | M833: 2024-06-25 | N833: =O833&P833 -> Новикова Ольга ПетровнаСеменов Михаил Никитич | O833: Новикова Ольга Петровна | P833: Семенов Михаил Никитич | Q833: 2023-11-06
J834: =K834&L834 -> Фролов Сергей ВикторовичИванова София Ильинична | K834: Фролов Сергей Викторович | L834: Иванова София Ильинична | M834: 2024-06-25 | N834: =O834&P834 -> Новикова Ольга ПетровнаСтепанов Матвей Михайлович | O834: Новикова Ольга Петровна | P834: Степанов Матвей Михайлович | Q834: 2023-11-06
J835: =K835&L835 -> Белов Алексей КонстантиновичНовикова Анна Ильинична | K835: Белов Алексей Константинович | L835: Новикова Анна Ильинична | M835: 2024-06-26 | N835: =O835&P835 -> Ткаченко Андрей ОлеговичЛебедева Александра Станиславовна | O835: Ткаченко Андрей Олегович | P835: Лебедева Александра Станиславовна | Q835: 2023-11-06
J836: =K836&L836 -> Петров Владимир КирилловичКозлов Андрей Ильич | K836: Петров Владимир Кириллович | L836: Козлов Андрей Ильич | M836: 2024-06-27 | N836: =O836&P836 -> Орлов Павел ДенисовичФедоров Алексей Павлович | O836: Орлов Павел Денисович | P836: Федоров Алексей Павлович | Q836: 2023-11-06
J837: =K837&L837 -> Семенова Ирина ВалерьевнаПавлова Валерия Станиславовна | K837: Семенова Ирина Валерьевна | L837: Павлова Валерия Станиславовна | M837: 2024-06-27 | N837: =O837&P837 -> Ткаченко Андрей ОлеговичПетров Михаил Егорович | O837: Ткаченко Андрей Олегович | P837: Петров Михаил Егорович | Q837: 2023-11-06
J838: =K838&L838 -> Громова Мария ИльиничнаМорозова Татьяна Кирилловна | K838: Громова Мария Ильинична | L838: Морозова Татьяна Кирилловна | M838: 2024-06-27 | N838: =O838&P838 -> Новикова Ольга ПетровнаКузнецов Матвей Олегович | O838: Новикова Ольга Петровна | P838: Кузнецов Матвей Олегович | Q838: 2023-11-06
J839: =K839&L839 -> Яковлев Артем ИгоревичКузнецов Матвей Олегович | K839: Яковлев Артем Игоревич | L839: Кузнецов Матвей Олегович | M839: 2024-06-28 | N839: =O839&P839 -> Фролов Сергей ВикторовичПавлов Кирилл Иванович | O839: Фролов Сергей Викторович | P839: Павлов Кирилл Иванович | Q839: 2023-11-06
J840: =K840&L840 -> Кузнецов Дмитрий ЛьвовичВолкова Анна Кирилловна | K840: Кузнецов Дмитрий Львович | L840: Волкова Анна Кирилловна | M840: 2024-06-28 | N840: =O840&P840 -> Семенова Ирина ВалерьевнаИванов Павел Сергеевич | O840: Семенова Ирина Валерьевна | P840: Иванов Павел Сергеевич | Q840: 2023-11-06
... J1001: =K1001&L1001 -> Фролов Сергей ВикторовичФедоров Алексей Павлович | K1001: Фролов Сергей Викторович | L1001: Федоров Алексей Павлович | M1001: 2024-09-02 | N1001: =O1001&P1001 -> Фролов Сергей ВикторовичОрлова Анна Владимировна | O1001: Фролов Сергей Викторович | P1001: Орлова Анна Владимировна | Q1001: 2023-09-01

Sheet Задание1.1
A1: ФИО менеджера | B1: ФИО клиента | C1: первый проект | D1: последний проект | E1: Дни
A2: Кузнецов Дмитрий Львович | B2: Иванова Валерия Алексеевна | C2: 2023-09-12 | D2: 2024-08-26 | E2: 349
A3: Петров Владимир Кириллович | B3: Семенов Константин Артемович | C3: 2023-10-02 | D3: 2024-08-22 | E3: 325
A4: Громова Мария Ильинична | B4: Сидоров Алексей Кириллович | C4: 2023-09-04 | D4: 2024-07-22 | E4: 322
A5: Белов Алексей Константинович | B5: Алексеев Иван Иванович | C5: 2023-09-20 | D5: 2024-07-31 | E5: 315
A6: Громова Мария Ильинична | B6: Орлова Дарья Владимировна | C6: 2023-09-28 | D6: 2024-08-08 | E6: 315
A7: Семенова Ирина Валерьевна | B7: Алексеева Наталья Андреевна | C7: 2023-10-17 | D7: 2024-08-27 | E7: 315
A8: Новикова Ольга Петровна | B8: Степанов Матвей Михайлович | C8: 2023-11-06 | D8: 2024-08-27 | E8: 295
A9: Ткаченко Андрей Олегович | B9: Федорова Анна Михайловна | C9: 2023-10-27 | D9: 2024-08-15 | E9: 293
A10: Иванова Анна Сергеевна | B10: Попова Ксения Никитична | C10: 2023-09-04 | D10: 2024-06-10 | E10: 280
A11: Сидорова Елена Васильевна | B11: Васильева Мария Ивановна | C11: 2023-10-18 | D11: 2024-07-12 | E11: 268
A12: Громова Мария Ильинична | B12: Новикова Людмила Павловна | C12: 2023-11-13 | D12: 2024-07-31 | E12: 261
A13: Новикова Ольга Петровна | B13: Смирнова Екатерина Егоровна | C13: 2023-11-29 | D13: 2024-08-16 | E13: 261
... A828: Яковлев Артем Игоревич | B828: Федорова Мария Ивановна | C828: 2024-06-03 | D828: 2024-06-03 | E828: 0

Sheet Задание2
A1: ФИО клиента | B1: Проекты | C1: Сумма | D1: Менеджеры
A2: Алексеев Иван Иванович | B2: 7 | C2: 324443 | D2: =COUNTIF('Задание1'!E:E,A2) -> 4
A3: Алексеева Анна Олеговна | B3: 3 | C3: 224761 | D3: =COUNTIF('Задание1'!E:E,A3) -> 2
A4: Алексеева Екатерина Павловна | B4: 7 | C4: 365996 | D4: =COUNTIF('Задание1'!E:E,A4) -> 6
A5: Алексеева Ирина Андреевна | B5: 8 | C5: 391688 | D5: =COUNTIF('Задание1'!E:E,A5) -> 6
A6: Алексеева Наталья Андреевна | B6: 9 | C6: 620614 | D6: =COUNTIF('Задание1'!E:E,A6) -> 6
A7: Алексеева София Андреевна | B7: 2 | C7: 105213 | D7: =COUNTIF('Задание1'!E:E,A7) -> 2
A8: Васильев Александр Павлович | B8: 7 | C8: 461901 | D8: =COUNTIF('Задание1'!E:E,A8) -> 6
A9: Васильев Алексей Андреевич | B9: 4 | C9: 238125 | D9: =COUNTIF('Задание1'!E:E,A9) -> 4
A10: Васильев Дмитрий Алексеевич | B10: 5 | C10: 287799 | D10: =COUNTIF('Задание1'!E:E,A10) -> 4
A11: Васильев Дмитрий Михайлович | B11: 2 | C11: 101151 | D11: =COUNTIF('Задание1'!E:E,A11) -> 2
A12: Васильев Кирилл Иванович | B12: 8 | C12: 478952 | D12: =COUNTIF('Задание1'!E:E,A12) -> 7
A13: Васильева Анна Ильинична | B13: 7 | C13: 394255 | D13: =COUNTIF('Задание1'!E:E,A13) -> 5
... A197: Федорова Мария Ивановна | B197: 4 | C197: 240878 | D197: =COUNTIF('Задание1'!E:E,A197) -> 4

Sheet Задание3
B1: 2023-9 | C1: 2023-10 | D1: 2023-11 | E1: 2023-12 | F1: 2024-1 | G1: 2024-2 | H1: 2024-3 | I1: 2024-4 | J1: 2024-5 | K1: 2024-6 | L1: 2024-7 | M1: 2024-8 | N1: 2024-9
A2: Белов Алексей Константинович | B2: =COUNTIFS('Задача3.1'!$A:$A,$A2,'Задача3.1'!$H:$H,B$1) -> 0 | C2: =COUNTIFS('Задача3.1'!$A:$A,$A2,'Задача3.1'!$H:$H,C$1) -> 1 | D2: =COUNTIFS('Задача3.1'!$A:$A,$A2,'Задача3.1'!$H:$H,D$1) -> 1 | E2: =COUNTIFS('Задача3.1'!$A:$A,$A2,'Задача3.1'!$H:$H,E$1) -> 2 | F2: =COUNTIFS('Задача3.1'!$A:$A,$A2,'Задача3.1'!$H:$H,F$1) -> 3 | G2: =COUNTIFS('Задача3.1'!$A:$A,$A2,'Задача3.1'!$H:$H,G$1) -> 1 | H2: =COUNTIFS('Задача3.1'!$A:$A,$A2,'Задача3.1'!$H:$H,H$1) -> 4 | I2: =COUNTIFS('Задача3.1'!$A:$A,$A2,'Задача3.1'!$H:$H,I$1) -> 3 | ... N2: =COUNTIFS('Задача3.1'!$A:$A,$A2,'Задача3.1'!$H:$H,N$1) -> 1
A3: Громова Мария Ильинична | B3: =COUNTIFS('Задача3.1'!$A:$A,$A3,'Задача3.1'!$H:$H,B$1) -> 1 | C3: =COUNTIFS('Задача3.1'!$A:$A,$A3,'Задача3.1'!$H:$H,C$1) -> 1 | D3: =COUNTIFS('Задача3.1'!$A:$A,$A3,'Задача3.1'!$H:$H,D$1) -> 1 | E3: =COUNTIFS('Задача3.1'!$A:$A,$A3,'Задача3.1'!$H:$H,E$1) -> 0 | F3: =COUNTIFS('Задача3.1'!$A:$A,$A3,'Задача3.1'!$H:$H,F$1) -> 3 | G3: =COUNTIFS('Задача3.1'!$A:$A,$A3,'Задача3.1'!$H:$H,G$1) -> 4 | H3: =COUNTIFS('Задача3.1'!$A:$A,$A3,'Задача3.1'!$H:$H,H$1) -> 1 | I3: =COUNTIFS('Задача3.1'!$A:$A,$A3,'Задача3.1'!$H:$H,I$1) -> 3 | ... N3: =COUNTIFS('Задача3.1'!$A:$A,$A3,'Задача3.1'!$H:$H,N$1) -> 0
A4: Иванова Анна Сергеевна | B4: =COUNTIFS('Задача3.1'!$A:$A,$A4,'Задача3.1'!$H:$H,B$1) -> 2 | C4: =COUNTIFS('Задача3.1'!$A:$A,$A4,'Задача3.1'!$H:$H,C$1) -> 1 | D4: =COUNTIFS('Задача3.1'!$A:$A,$A4,'Задача3.1'!$H:$H,D$1) -> 0 | E4: =COUNTIFS('Задача3.1'!$A:$A,$A4,'Задача3.1'!$H:$H,E$1) -> 0 | F4: =COUNTIFS('Задача3.1'!$A:$A,$A4,'Задача3.1'!$H:$H,F$1) -> 1 | G4: =COUNTIFS('Задача3.1'!$A:$A,$A4,'Задача3.1'!$H:$H,G$1) -> 1 | H4: =COUNTIFS('Задача3.1'!$A:$A,$A4,'Задача3.1'!$H:$H,H$1) -> 1 | I4: =COUNTIFS('Задача3.1'!$A:$A,$A4,'Задача3.1'!$H:$H,I$1) -> 0 | ... N4: =COUNTIFS('Задача3.1'!$A:$A,$A4,'Задача3.1'!$H:$H,N$1) -> 0
A5: Кузнецов Дмитрий Львович | B5: =COUNTIFS('Задача3.1'!$A:$A,$A5,'Задача3.1'!$H:$H,B$1) -> 1 | C5: =COUNTIFS('Задача3.1'!$A:$A,$A5,'Задача3.1'!$H:$H,C$1) -> 0 | D5: =COUNTIFS('Задача3.1'!$A:$A,$A5,'Задача3.1'!$H:$H,D$1) -> 4 | E5: =COUNTIFS('Задача3.1'!$A:$A,$A5,'Задача3.1'!$H:$H,E$1) -> 2 | F5: =COUNTIFS('Задача3.1'!$A:$A,$A5,'Задача3.1'!$H:$H,F$1) -> 1 | G5: =COUNTIFS('Задача3.1'!$A:$A,$A5,'Задача3.1'!$H:$H,G$1) -> 1 | H5: =COUNTIFS('Задача3.1'!$A:$A,$A5,'Задача3.1'!$H:$H,H$1) -> 4 | I5: =COUNTIFS('Задача3.1'!$A:$A,$A5,'Задача3.1'!$H:$H,I$1) -> 0 | ... N5: =COUNTIFS('Задача3.1'!$A:$A,$A5,'Задача3.1'!$H:$H,N$1) -> 1
A6: Новикова Ольга Петровна | B6: =COUNTIFS('Задача3.1'!$A:$A,$A6,'Задача3.1'!$H:$H,B$1) -> 1 | C6: =COUNTIFS('Задача3.1'!$A:$A,$A6,'Задача3.1'!$H:$H,C$1) -> 0 | D6: =COUNTIFS('Задача3.1'!$A:$A,$A6,'Задача3.1'!$H:$H,D$1) -> 0 | E6: =COUNTIFS('Задача3.1'!$A:$A,$A6,'Задача3.1'!$H:$H,E$1) -> 0 | F6: =COUNTIFS('Задача3.1'!$A:$A,$A6,'Задача3.1'!$H:$H,F$1) -> 2 | G6: =COUNTIFS('Задача3.1'!$A:$A,$A6,'Задача3.1'!$H:$H,G$1) -> 2 | H6: =COUNTIFS('Задача3.1'!$A:$A,$A6,'Задача3.1'!$H:$H,H$1) -> 1 | I6: =COUNTIFS('Задача3.1'!$A:$A,$A6,'Задача3.1'!$H:$H,I$1) -> 2 | ... N6: =COUNTIFS('Задача3.1'!$A:$A,$A6,'Задача3.1'!$H:$H,N$1) -> 3
A7: Орлов Павел Денисович | B7: =COUNTIFS('Задача3.1'!$A:$A,$A7,'Задача3.1'!$H:$H,B$1) -> 2 | C7: =COUNTIFS('Задача3.1'!$A:$A,$A7,'Задача3.1'!$H:$H,C$1) -> 0 | D7: =COUNTIFS('Задача3.1'!$A:$A,$A7,'Задача3.1'!$H:$H,D$1) -> 2 | E7: =COUNTIFS('Задача3.1'!$A:$A,$A7,'Задача3.1'!$H:$H,E$1) -> 1 | F7: =COUNTIFS('Задача3.1'!$A:$A,$A7,'Задача3.1'!$H:$H,F$1) -> 1 | G7: =COUNTIFS('Задача3.1'!$A:$A,$A7,'Задача3.1'!$H:$H,G$1) -> 0 | H7: =COUNTIFS('Задача3.1'!$A:$A,$A7,'Задача3.1'!$H:$H,H$1) -> 3 | I7: =COUNTIFS('Задача3.1'!$A:$A,$A7,'Задача3.1'!$H:$H,I$1) -> 3 | ... N7: =COUNTIFS('Задача3.1'!$A:$A,$A7,'Задача3.1'!$H:$H,N$1) -> 1
A8: Петров Владимир Кириллович | B8: =COUNTIFS('Задача3.1'!$A:$A,$A8,'Задача3.1'!$H:$H,B$1) -> 0 | C8: =COUNTIFS('Задача3.1'!$A:$A,$A8,'Задача3.1'!$H:$H,C$1) -> 0 | D8: =COUNTIFS('Задача3.1'!$A:$A,$A8,'Задача3.1'!$H:$H,D$1) -> 2 | E8: =COUNTIFS('Задача3.1'!$A:$A,$A8,'Задача3.1'!$H:$H,E$1) -> 0 | F8: =COUNTIFS('Задача3.1'!$A:$A,$A8,'Задача3.1'!$H:$H,F$1) -> 1 | G8: =COUNTIFS('Задача3.1'!$A:$A,$A8,'Задача3.1'!$H:$H,G$1) -> 0 | H8: =COUNTIFS('Задача3.1'!$A:$A,$A8,'Задача3.1'!$H:$H,H$1) -> 1 | I8: =COUNTIFS('Задача3.1'!$A:$A,$A8,'Задача3.1'!$H:$H,I$1) -> 0 | ... N8: =COUNTIFS('Задача3.1'!$A:$A,$A8,'Задача3.1'!$H:$H,N$1) -> 1
A9: Семенова Ирина Валерьевна | B9: =COUNTIFS('Задача3.1'!$A:$A,$A9,'Задача3.1'!$H:$H,B$1) -> 1 | C9: =COUNTIFS('Задача3.1'!$A:$A,$A9,'Задача3.1'!$H:$H,C$1) -> 1 | D9: =COUNTIFS('Задача3.1'!$A:$A,$A9,'Задача3.1'!$H:$H,D$1) -> 1 | E9: =COUNTIFS('Задача3.1'!$A:$A,$A9,'Задача3.1'!$H:$H,E$1) -> 1 | F9: =COUNTIFS('Задача3.1'!$A:$A,$A9,'Задача3.1'!$H:$H,F$1) -> 3 | G9: =COUNTIFS('Задача3.1'!$A:$A,$A9,'Задача3.1'!$H:$H,G$1) -> 0 | H9: =COUNTIFS('Задача3.1'!$A:$A,$A9,'Задача3.1'!$H:$H,H$1) -> 2 | I9: =COUNTIFS('Задача3.1'!$A:$A,$A9,'Задача3.1'!$H:$H,I$1) -> 3 | ... N9: =COUNTIFS('Задача3.1'!$A:$A,$A9,'Задача3.1'!$H:$H,N$1) -> 0
A10: Сидорова Елена Васильевна | B10: =COUNTIFS('Задача3.1'!$A:$A,$A10,'Задача3.1'!$H:$H,B$1) -> 1 | C10: =COUNTIFS('Задача3.1'!$A:$A,$A10,'Задача3.1'!$H:$H,C$1) -> 1 | D10: =COUNTIFS('Задача3.1'!$A:$A,$A10,'Задача3.1'!$H:$H,D$1) -> 3 | E10: =COUNTIFS('Задача3.1'!$A:$A,$A10,'Задача3.1'!$H:$H,E$1) -> 2 | F10: =COUNTIFS('Задача3.1'!$A:$A,$A10,'Задача3.1'!$H:$H,F$1) -> 2 | G10: =COUNTIFS('Задача3.1'!$A:$A,$A10,'Задача3.1'!$H:$H,G$1) -> 0 | H10: =COUNTIFS('Задача3.1'!$A:$A,$A10,'Задача3.1'!$H:$H,H$1) -> 1 | I10: =COUNTIFS('Задача3.1'!$A:$A,$A10,'Задача3.1'!$H:$H,I$1) -> 2 | ... N10: =COUNTIFS('Задача3.1'!$A:$A,$A10,'Задача3.1'!$H:$H,N$1) -> 1
A11: Ткаченко Андрей Олегович | B11: =COUNTIFS('Задача3.1'!$A:$A,$A11,'Задача3.1'!$H:$H,B$1) -> 2 | C11: =COUNTIFS('Задача3.1'!$A:$A,$A11,'Задача3.1'!$H:$H,C$1) -> 1 | D11: =COUNTIFS('Задача3.1'!$A:$A,$A11,'Задача3.1'!$H:$H,D$1) -> 0 | E11: =COUNTIFS('Задача3.1'!$A:$A,$A11,'Задача3.1'!$H:$H,E$1) -> 0 | F11: =COUNTIFS('Задача3.1'!$A:$A,$A11,'Задача3.1'!$H:$H,F$1) -> 4 | G11: =COUNTIFS('Задача3.1'!$A:$A,$A11,'Задача3.1'!$H:$H,G$1) -> 0 | H11: =COUNTIFS('Задача3.1'!$A:$A,$A11,'Задача3.1'!$H:$H,H$1) -> 2 | I11: =COUNTIFS('Задача3.1'!$A:$A,$A11,'Задача3.1'!$H:$H,I$1) -> 2 | ... N11: =COUNTIFS('Задача3.1'!$A:$A,$A11,'Задача3.1'!$H:$H,N$1) -> 1
A12: Фролов Сергей Викторович | B12: =COUNTIFS('Задача3.1'!$A:$A,$A12,'Задача3.1'!$H:$H,B$1) -> 1 | C12: =COUNTIFS('Задача3.1'!$A:$A,$A12,'Задача3.1'!$H:$H,C$1) -> 2 | D12: =COUNTIFS('Задача3.1'!$A:$A,$A12,'Задача3.1'!$H:$H,D$1) -> 3 | E12: =COUNTIFS('Задача3.1'!$A:$A,$A12,'Задача3.1'!$H:$H,E$1) -> 0 | F12: =COUNTIFS('Задача3.1'!$A:$A,$A12,'Задача3.1'!$H:$H,F$1) -> 5 | G12: =COUNTIFS('Задача3.1'!$A:$A,$A12,'Задача3.1'!$H:$H,G$1) -> 3 | H12: =COUNTIFS('Задача3.1'!$A:$A,$A12,'Задача3.1'!$H:$H,H$1) -> 2 | I12: =COUNTIFS('Задача3.1'!$A:$A,$A12,'Задача3.1'!$H:$H,I$1) -> 0 | ... N12: =COUNTIFS('Задача3.1'!$A:$A,$A12,'Задача3.1'!$H:$H,N$1) -> 4
A13: Яковлев Артем Игоревич | B13: =COUNTIFS('Задача3.1'!$A:$A,$A13,'Задача3.1'!$H:$H,B$1) -> 0 | C13: =COUNTIFS('Задача3.1'!$A:$A,$A13,'Задача3.1'!$H:$H,C$1) -> 0 | D13: =COUNTIFS('Задача3.1'!$A:$A,$A13,'Задача3.1'!$H:$H,D$1) -> 2 | E13: =COUNTIFS('Задача3.1'!$A:$A,$A13,'Задача3.1'!$H:$H,E$1) -> 0 | F13: =COUNTIFS('Задача3.1'!$A:$A,$A13,'Задача3.1'!$H:$H,F$1) -> 2 | G13: =COUNTIFS('Задача3.1'!$A:$A,$A13,'Задача3.1'!$H:$H,G$1) -> 2 | H13: =COUNTIFS('Задача3.1'!$A:$A,$A13,'Задача3.1'!$H:$H,H$1) -> 4 | I13: =COUNTIFS('Задача3.1'!$A:$A,$A13,'Задача3.1'!$H:$H,I$1) -> 0 | ... N13: =COUNTIFS('Задача3.1'!$A:$A,$A13,'Задача3.1'!$H:$H,N$1) -> 1
A15: - месяц / кол-во проектов на одного менеджера

Sheet Задача3.1
A1: ФИО менеджера | B1: ФИО клиента | C1: Дата сделки | D1: Сумма сделки | E1: NPS | F1: Год | G1: Месяц | H1: Год.меесяц
A2: Фролов Сергей Викторович | B2: Орлова Анна Владимировна | C2: 2023-09-01 | D2: 62110 | E2: 5 | F2: =YEAR(C2) -> 2023 | G2: =MONTH(C2) -> 1 | H2: =F2&"-"&G2 -> 2023-1
A3: Кузнецов Дмитрий Львович | B3: Иванова Анна Геннадьевна | C3: 2023-09-04 | D3: 73955 | E3: 7 | F3: =YEAR(C3) -> 2023 | G3: =MONTH(C3) -> 4 | H3: =F3&"-"&G3 -> 2023-4
A4: Иванова Анна Сергеевна | B4: Егорова Татьяна Ильинична | C4: 2023-09-04 | D4: 60135 | E4: 8 | F4: =YEAR(C4) -> 2023 | G4: =MONTH(C4) -> 4 | H4: =F4&"-"&G4 -> 2023-4
A5: Громова Мария Ильинична | B5: Сидоров Алексей Кириллович | C5: 2023-09-04 | D5: 59782 | E5: 8 | F5: =YEAR(C5) -> 2023 | G5: =MONTH(C5) -> 4 | H5: =F5&"-"&G5 -> 2023-4
A6: Сидорова Елена Васильевна | B6: Иванов Матвей Юрьевич | C6: 2023-09-04 | D6: 71041 | E6: 0 | F6: =YEAR(C6) -> 2023 | G6: =MONTH(C6) -> 4 | H6: =F6&"-"&G6 -> 2023-4
A7: Новикова Ольга Петровна | B7: Васильев Дмитрий Алексеевич | C7: 2023-09-04 | D7: 62764 | E7: 7 | F7: =YEAR(C7) -> 2023 | G7: =MONTH(C7) -> 4 | H7: =F7&"-"&G7 -> 2023-4
A8: Кузнецов Дмитрий Львович | B8: Орлова Людмила Артемовна | C8: 2023-09-04 | D8: 97781 | E8: 10 | F8: =YEAR(C8) -> 2023 | G8: =MONTH(C8) -> 4 | H8: =F8&"-"&G8 -> 2023-4
A9: Иванова Анна Сергеевна | B9: Попова Ксения Никитична | C9: 2023-09-04 | D9: 32384 | E9: 8 | F9: =YEAR(C9) -> 2023 | G9: =MONTH(C9) -> 4 | H9: =F9&"-"&G9 -> 2023-4
A10: Яковлев Артем Игоревич | B10: Кузнецов Дмитрий Андреевич | C10: 2023-09-05 | D10: 74878 | E10: 4 | F10: =YEAR(C10) -> 2023 | G10: =MONTH(C10) -> 5 | H10: =F10&"-"&G10 -> 2023-5
A11: Ткаченко Андрей Олегович | B11: Павлов Кирилл Иванович | C11: 2023-09-05 | D11: 72619 | E11: 7 | F11: =YEAR(C11) -> 2023 | G11: =MONTH(C11) -> 5 | H11: =F11&"-"&G11 -> 2023-5
A12: Новикова Ольга Петровна | B12: Егоров Владимир Артемович | C12: 2023-09-06 | D12: 41496 | E12: 7 | F12: =YEAR(C12) -> 2023 | G12: =MONTH(C12) -> 6 | H12: =F12&"-"&G12 -> 2023-6
A13: Петров Владимир Кириллович | B13: Кузнецова Юлия Павловна | C13: 2023-09-06 | D13: 84622 | E13: 7 | F13: =YEAR(C13) -> 2023 | G13: =MONTH(C13) -> 6 | H13: =F13&"-"&G13 -> 2023-6
... A1001: Фролов Сергей Викторович | B1001: Федоров Алексей Павлович | C1001: 2024-09-02 | D1001: 76169 | E1001: 7 | F1001: =YEAR(C1001) -> 2024 | G1001: =MONTH(C1001) -> 2 | H1001: =F1001&"-"&G1001 -> 2024-2

Sheet Задача3.2
B1: 2023-9 | C1: 2023-10 | D1: 2023-11 | E1: 2023-12 | F1: 2024-1 | G1: 2024-2 | H1: 2024-3 | I1: 2024-4 | J1: 2024-5 | K1: 2024-6 | L1: 2024-7 | M1: 2024-8 | N1: 2024-9
A2: Белов Алексей Константинович | B2: =IFERROR((COUNTIFS('Задача3.1'!$A:$A,$A2,'Задача3.1'!$H:$H,B$1,'Задача3.1'!$E:$E,">=9")-COUNTIFS('Задача3.1'!$A:$A,$A2,'Задача3.1'!$H:$H,B$1,'Задача3.1'!$E:$E,"<=6"))/COUNTIFS('Задача3.1'!$A:$A,$A2,'Задача3.1'!$H:$H,B$1,'Задача3.1'!$E:$E,">=0"),"") | C2: =IFERROR((COUNTIFS('Задача3.1'!$A:$A,$A2,'Задача3.1'!$H:$H,C$1,'Задача3.1'!$E:$E,">=9")-COUNTIFS('Задача3.1'!$A:$A,$A2,'Задача3.1'!$H:$H,C$1,'Задача3.1'!$E:$E,"<=6"))/COUNTIFS('Задача3.1'!$A:$A,$A2,'Задача3.1'!$H:$H,C$1,'Задача3.1'!$E:$E,">=0"),"") -> 1 | D2: =IFERROR((COUNTIFS('Задача3.1'!$A:$A,$A2,'Задача3.1'!$H:$H,D$1,'Задача3.1'!$E:$E,">=9")-COUNTIFS('Задача3.1'!$A:$A,$A2,'Задача3.1'!$H:$H,D$1,'Задача3.1'!$E:$E,"<=6"))/COUNTIFS('Задача3.1'!$A:$A,$A2,'Задача3.1'!$H:$H,D$1,'Задача3.1'!$E:$E,">=0"),"") -> 0 | E2: =IFERROR((COUNTIFS('Задача3.1'!$A:$A,$A2,'Задача3.1'!$H:$H,E$1,'Задача3.1'!$E:$E,">=9")-COUNTIFS('Задача3.1'!$A:$A,$A2,'Задача3.1'!$H:$H,E$1,'Задача3.1'!$E:$E,"<=6"))/COUNTIFS('Задача3.1'!$A:$A,$A2,'Задача3.1'!$H:$H,E$1,'Задача3.1'!$E:$E,">=0"),"") -> -0.5 | F2: =IFERROR((COUNTIFS('Задача3.1'!$A:$A,$A2,'Задача3.1'!$H:$H,F$1,'Задача3.1'!$E:$E,">=9")-COUNTIFS('Задача3.1'!$A:$A,$A2,'Задача3.1'!$H:$H,F$1,'Задача3.1'!$E:$E,"<=6"))/COUNTIFS('Задача3.1'!$A:$A,$A2,'Задача3.1'!$H:$H,F$1,'Задача3.1'!$E:$E,">=0"),"") -> -1 | G2: =IFERROR((COUNTIFS('Задача3.1'!$A:$A,$A2,'Задача3.1'!$H:$H,G$1,'Задача3.1'!$E:$E,">=9")-COUNTIFS('Задача3.1'!$A:$A,$A2,'Задача3.1'!$H:$H,G$1,'Задача3.1'!$E:$E,"<=6"))/COUNTIFS('Задача3.1'!$A:$A,$A2,'Задача3.1'!$H:$H,G$1,'Задача3.1'!$E:$E,">=0"),"") -> 0 | H2: =IFERROR((COUNTIFS('Задача3.1'!$A:$A,$A2,'Задача3.1'!$H:$H,H$1,'Задача3.1'!$E:$E,">=9")-COUNTIFS('Задача3.1'!$A:$A,$A2,'Задача3.1'!$H:$H,H$1,'Задача3.1'!$E:$E,"<=6"))/COUNTIFS('Задача3.1'!$A:$A,$A2,'Задача3.1'!$H:$H,H$1,'Задача3.1'!$E:$E,">=0"),"") -> -0.5 | I2: =IFERROR((COUNTIFS('Задача3.1'!$A:$A,$A2,'Задача3.1'!$H:$H,I$1,'Задача3.1'!$E:$E,">=9")-COUNTIFS('Задача3.1'!$A:$A,$A2,'Задача3.1'!$H:$H,I$1,'Задача3.1'!$E:$E,"<=6"))/COUNTIFS('Задача3.1'!$A:$A,$A2,'Задача3.1'!$H:$H,I$1,'Задача3.1'!$E:$E,">=0"),"") -> 0 | ... N2: =IFERROR((COUNTIFS('Задача3.1'!$A:$A,$A2,'Задача3.1'!$H:$H,N$1,'Задача3.1'!$E:$E,">=9")-COUNTIFS('Задача3.1'!$A:$A,$A2,'Задача3.1'!$H:$H,N$1,'Задача3.1'!$E:$E,"<=6"))/COUNTIFS('Задача3.1'!$A:$A,$A2,'Задача3.1'!$H:$H,N$1,'Задача3.1'!$E:$E,">=0"),"") -> -1
A3: Громова Мария Ильинична | B3: =IFERROR((COUNTIFS('Задача3.1'!$A:$A,$A3,'Задача3.1'!$H:$H,B$1,'Задача3.1'!$E:$E,">=9")-COUNTIFS('Задача3.1'!$A:$A,$A3,'Задача3.1'!$H:$H,B$1,'Задача3.1'!$E:$E,"<=6"))/COUNTIFS('Задача3.1'!$A:$A,$A3,'Задача3.1'!$H:$H,B$1,'Задача3.1'!$E:$E,">=0"),"") -> -1 | C3: =IFERROR((COUNTIFS('Задача3.1'!$A:$A,$A3,'Задача3.1'!$H:$H,C$1,'Задача3.1'!$E:$E,">=9")-COUNTIFS('Задача3.1'!$A:$A,$A3,'Задача3.1'!$H:$H,C$1,'Задача3.1'!$E:$E,"<=6"))/COUNTIFS('Задача3.1'!$A:$A,$A3,'Задача3.1'!$H:$H,C$1,'Задача3.1'!$E:$E,">=0"),"") -> 0 | D3: =IFERROR((COUNTIFS('Задача3.1'!$A:$A,$A3,'Задача3.1'!$H:$H,D$1,'Задача3.1'!$E:$E,">=9")-COUNTIFS('Задача3.1'!$A:$A,$A3,'Задача3.1'!$H:$H,D$1,'Задача3.1'!$E:$E,"<=6"))/COUNTIFS('Задача3.1'!$A:$A,$A3,'Задача3.1'!$H:$H,D$1,'Задача3.1'!$E:$E,">=0"),"") -> -1 | E3: =IFERROR((COUNTIFS('Задача3.1'!$A:$A,$A3,'Задача3.1'!$H:$H,E$1,'Задача3.1'!$E:$E,">=9")-COUNTIFS('Задача3.1'!$A:$A,$A3,'Задача3.1'!$H:$H,E$1,'Задача3.1'!$E:$E,"<=6"))/COUNTIFS('Задача3.1'!$A:$A,$A3,'Задача3.1'!$H:$H,E$1,'Задача3.1'!$E:$E,">=0"),"") | F3: =IFERROR((COUNTIFS('Задача3.1'!$A:$A,$A3,'Задача3.1'!$H:$H,F$1,'Задача3.1'!$E:$E,">=9")-COUNTIFS('Задача3.1'!$A:$A,$A3,'Задача3.1'!$H:$H,F$1,'Задача3.1'!$E:$E,"<=6"))/COUNTIFS('Задача3.1'!$A:$A,$A3,'Задача3.1'!$H:$H,F$1,'Задача3.1'!$E:$E,">=0"),"") -> 0.33333333 | G3: =IFERROR((COUNTIFS('Задача3.1'!$A:$A,$A3,'Задача3.1'!$H:$H,G$1,'Задача3.1'!$E:$E,">=9")-COUNTIFS('Задача3.1'!$A:$A,$A3,'Задача3.1'!$H:$H,G$1,'Задача3.1'!$E:$E,"<=6"))/COUNTIFS('Задача3.1'!$A:$A,$A3,'Задача3.1'!$H:$H,G$1,'Задача3.1'!$E:$E,">=0"),"") -> -0.75 | H3: =IFERROR((COUNTIFS('Задача3.1'!$A:$A,$A3,'Задача3.1'!$H:$H,H$1,'Задача3.1'!$E:$E,">=9")-COUNTIFS('Задача3.1'!$A:$A,$A3,'Задача3.1'!$H:$H,H$1,'Задача3.1'!$E:$E,"<=6"))/COUNTIFS('Задача3.1'!$A:$A,$A3,'Задача3.1'!$H:$H,H$1,'Задача3.1'!$E:$E,">=0"),"") -> -1 | I3: =IFERROR((COUNTIFS('Задача3.1'!$A:$A,$A3,'Задача3.1'!$H:$H,I$1,'Задача3.1'!$E:$E,">=9")-COUNTIFS('Задача3.1'!$A:$A,$A3,'Задача3.1'!$H:$H,I$1,'Задача3.1'!$E:$E,"<=6"))/COUNTIFS('Задача3.1'!$A:$A,$A3,'Задача3.1'!$H:$H,I$1,'Задача3.1'!$E:$E,">=0"),"") -> 0 | ... N3: =IFERROR((COUNTIFS('Задача3.1'!$A:$A,$A3,'Задача3.1'!$H:$H,N$1,'Задача3.1'!$E:$E,">=9")-COUNTIFS('Задача3.1'!$A:$A,$A3,'Задача3.1'!$H:$H,N$1,'Задача3.1'!$E:$E,"<=6"))/COUNTIFS('Задача3.1'!$A:$A,$A3,'Задача3.1'!$H:$H,N$1,'Задача3.1'!$E:$E,">=0"),"")
A4: Иванова Анна Сергеевна | B4: =IFERROR((COUNTIFS('Задача3.1'!$A:$A,$A4,'Задача3.1'!$H:$H,B$1,'Задача3.1'!$E:$E,">=9")-COUNTIFS('Задача3.1'!$A:$A,$A4,'Задача3.1'!$H:$H,B$1,'Задача3.1'!$E:$E,"<=6"))/COUNTIFS('Задача3.1'!$A:$A,$A4,'Задача3.1'!$H:$H,B$1,'Задача3.1'!$E:$E,">=0"),"") -> -0.5 | C4: =IFERROR((COUNTIFS('Задача3.1'!$A:$A,$A4,'Задача3.1'!$H:$H,C$1,'Задача3.1'!$E:$E,">=9")-COUNTIFS('Задача3.1'!$A:$A,$A4,'Задача3.1'!$H:$H,C$1,'Задача3.1'!$E:$E,"<=6"))/COUNTIFS('Задача3.1'!$A:$A,$A4,'Задача3.1'!$H:$H,C$1,'Задача3.1'!$E:$E,">=0"),"") -> -1 | D4: =IFERROR((COUNTIFS('Задача3.1'!$A:$A,$A4,'Задача3.1'!$H:$H,D$1,'Задача3.1'!$E:$E,">=9")-COUNTIFS('Задача3.1'!$A:$A,$A4,'Задача3.1'!$H:$H,D$1,'Задача3.1'!$E:$E,"<=6"))/COUNTIFS('Задача3.1'!$A:$A,$A4,'Задача3.1'!$H:$H,D$1,'Задача3.1'!$E:$E,">=0"),"") | E4: =IFERROR((COUNTIFS('Задача3.1'!$A:$A,$A4,'Задача3.1'!$H:$H,E$1,'Задача3.1'!$E:$E,">=9")-COUNTIFS('Задача3.1'!$A:$A,$A4,'Задача3.1'!$H:$H,E$1,'Задача3.1'!$E:$E,"<=6"))/COUNTIFS('Задача3.1'!$A:$A,$A4,'Задача3.1'!$H:$H,E$1,'Задача3.1'!$E:$E,">=0"),"") | F4: =IFERROR((COUNTIFS('Задача3.1'!$A:$A,$A4,'Задача3.1'!$H:$H,F$1,'Задача3.1'!$E:$E,">=9")-COUNTIFS('Задача3.1'!$A:$A,$A4,'Задача3.1'!$H:$H,F$1,'Задача3.1'!$E:$E,"<=6"))/COUNTIFS('Задача3.1'!$A:$A,$A4,'Задача3.1'!$H:$H,F$1,'Задача3.1'!$E:$E,">=0"),"") -> -1 | G4: =IFERROR((COUNTIFS('Задача3.1'!$A:$A,$A4,'Задача3.1'!$H:$H,G$1,'Задача3.1'!$E:$E,">=9")-COUNTIFS('Задача3.1'!$A:$A,$A4,'Задача3.1'!$H:$H,G$1,'Задача3.1'!$E:$E,"<=6"))/COUNTIFS('Задача3.1'!$A:$A,$A4,'Задача3.1'!$H:$H,G$1,'Задача3.1'!$E:$E,">=0"),"") -> -1 | H4: =IFERROR((COUNTIFS('Задача3.1'!$A:$A,$A4,'Задача3.1'!$H:$H,H$1,'Задача3.1'!$E:$E,">=9")-COUNTIFS('Задача3.1'!$A:$A,$A4,'Задача3.1'!$H:$H,H$1,'Задача3.1'!$E:$E,"<=6"))/COUNTIFS('Задача3.1'!$A:$A,$A4,'Задача3.1'!$H:$H,H$1,'Задача3.1'!$E:$E,">=0"),"") -> -1 | I4: =IFERROR((COUNTIFS('Задача3.1'!$A:$A,$A4,'Задача3.1'!$H:$H,I$1,'Задача3.1'!$E:$E,">=9")-COUNTIFS('Задача3.1'!$A:$A,$A4,'Задача3.1'!$H:$H,I$1,'Задача3.1'!$E:$E,"<=6"))/COUNTIFS('Задача3.1'!$A:$A,$A4,'Задача3.1'!$H:$H,I$1,'Задача3.1'!$E:$E,">=0"),"") | ... N4: =IFERROR((COUNTIFS('Задача3.1'!$A:$A,$A4,'Задача3.1'!$H:$H,N$1,'Задача3.1'!$E:$E,">=9")-COUNTIFS('Задача3.1'!$A:$A,$A4,'Задача3.1'!$H:$H,N$1,'Задача3.1'!$E:$E,"<=6"))/COUNTIFS('Задача3.1'!$A:$A,$A4,'Задача3.1'!$H:$H,N$1,'Задача3.1'!$E:$E,">=0"),"")
A5: Кузнецов Дмитрий Львович | B5: =IFERROR((COUNTIFS('Задача3.1'!$A:$A,$A5,'Задача3.1'!$H:$H,B$1,'Задача3.1'!$E:$E,">=9")-COUNTIFS('Задача3.1'!$A:$A,$A5,'Задача3.1'!$H:$H,B$1,'Задача3.1'!$E:$E,"<=6"))/COUNTIFS('Задача3.1'!$A:$A,$A5,'Задача3.1'!$H:$H,B$1,'Задача3.1'!$E:$E,">=0"),"") -> -1 | C5: =IFERROR((COUNTIFS('Задача3.1'!$A:$A,$A5,'Задача3.1'!$H:$H,C$1,'Задача3.1'!$E:$E,">=9")-COUNTIFS('Задача3.1'!$A:$A,$A5,'Задача3.1'!$H:$H,C$1,'Задача3.1'!$E:$E,"<=6"))/COUNTIFS('Задача3.1'!$A:$A,$A5,'Задача3.1'!$H:$H,C$1,'Задача3.1'!$E:$E,">=0"),"") | D5: =IFERROR((COUNTIFS('Задача3.1'!$A:$A,$A5,'Задача3.1'!$H:$H,D$1,'Задача3.1'!$E:$E,">=9")-COUNTIFS('Задача3.1'!$A:$A,$A5,'Задача3.1'!$H:$H,D$1,'Задача3.1'!$E:$E,"<=6"))/COUNTIFS('Задача3.1'!$A:$A,$A5,'Задача3.1'!$H:$H,D$1,'Задача3.1'!$E:$E,">=0"),"") -> -1 | E5: =IFERROR((COUNTIFS('Задача3.1'!$A:$A,$A5,'Задача3.1'!$H:$H,E$1,'Задача3.1'!$E:$E,">=9")-COUNTIFS('Задача3.1'!$A:$A,$A5,'Задача3.1'!$H:$H,E$1,'Задача3.1'!$E:$E,"<=6"))/COUNTIFS('Задача3.1'!$A:$A,$A5,'Задача3.1'!$H:$H,E$1,'Задача3.1'!$E:$E,">=0"),"") -> 0 | F5: =IFERROR((COUNTIFS('Задача3.1'!$A:$A,$A5,'Задача3.1'!$H:$H,F$1,'Задача3.1'!$E:$E,">=9")-COUNTIFS('Задача3.1'!$A:$A,$A5,'Задача3.1'!$H:$H,F$1,'Задача3.1'!$E:$E,"<=6"))/COUNTIFS('Задача3.1'!$A:$A,$A5,'Задача3.1'!$H:$H,F$1,'Задача3.1'!$E:$E,">=0"),"") -> 0 | G5: =IFERROR((COUNTIFS('Задача3.1'!$A:$A,$A5,'Задача3.1'!$H:$H,G$1,'Задача3.1'!$E:$E,">=9")-COUNTIFS('Задача3.1'!$A:$A,$A5,'Задача3.1'!$H:$H,G$1,'Задача3.1'!$E:$E,"<=6"))/COUNTIFS('Задача3.1'!$A:$A,$A5,'Задача3.1'!$H:$H,G$1,'Задача3.1'!$E:$E,">=0"),"") -> 1 | H5: =IFERROR((COUNTIFS('Задача3.1'!$A:$A,$A5,'Задача3.1'!$H:$H,H$1,'Задача3.1'!$E:$E,">=9")-COUNTIFS('Задача3.1'!$A:$A,$A5,'Задача3.1'!$H:$H,H$1,'Задача3.1'!$E:$E,"<=6"))/COUNTIFS('Задача3.1'!$A:$A,$A5,'Задача3.1'!$H:$H,H$1,'Задача3.1'!$E:$E,">=0"),"") -> -0.5 | I5: =IFERROR((COUNTIFS('Задача3.1'!$A:$A,$A5,'Задача3.1'!$H:$H,I$1,'Задача3.1'!$E:$E,">=9")-COUNTIFS('Задача3.1'!$A:$A,$A5,'Задача3.1'!$H:$H,I$1,'Задача3.1'!$E:$E,"<=6"))/COUNTIFS('Задача3.1'!$A:$A,$A5,'Задача3.1'!$H:$H,I$1,'Задача3.1'!$E:$E,">=0"),"") | ... N5: =IFERROR((COUNTIFS('Задача3.1'!$A:$A,$A5,'Задача3.1'!$H:$H,N$1,'Задача3.1'!$E:$E,">=9")-COUNTIFS('Задача3.1'!$A:$A,$A5,'Задача3.1'!$H:$H,N$1,'Задача3.1'!$E:$E,"<=6"))/COUNTIFS('Задача3.1'!$A:$A,$A5,'Задача3.1'!$H:$H,N$1,'Задача3.1'!$E:$E,">=0"),"") -> 0
A6: Новикова Ольга Петровна | B6: =IFERROR((COUNTIFS('Задача3.1'!$A:$A,$A6,'Задача3.1'!$H:$H,B$1,'Задача3.1'!$E:$E,">=9")-COUNTIFS('Задача3.1'!$A:$A,$A6,'Задача3.1'!$H:$H,B$1,'Задача3.1'!$E:$E,"<=6"))/COUNTIFS('Задача3.1'!$A:$A,$A6,'Задача3.1'!$H:$H,B$1,'Задача3.1'!$E:$E,">=0"),"") -> 1 | C6: =IFERROR((COUNTIFS('Задача3.1'!$A:$A,$A6,'Задача3.1'!$H:$H,C$1,'Задача3.1'!$E:$E,">=9")-COUNTIFS('Задача3.1'!$A:$A,$A6,'Задача3.1'!$H:$H,C$1,'Задача3.1'!$E:$E,"<=6"))/COUNTIFS('Задача3.1'!$A:$A,$A6,'Задача3.1'!$H:$H,C$1,'Задача3.1'!$E:$E,">=0"),"") | D6: =IFERROR((COUNTIFS('Задача3.1'!$A:$A,$A6,'Задача3.1'!$H:$H,D$1,'Задача3.1'!$E:$E,">=9")-COUNTIFS('Задача3.1'!$A:$A,$A6,'Задача3.1'!$H:$H,D$1,'Задача3.1'!$E:$E,"<=6"))/COUNTIFS('Задача3.1'!$A:$A,$A6,'Задача3.1'!$H:$H,D$1,'Задача3.1'!$E:$E,">=0"),"") | E6: =IFERROR((COUNTIFS('Задача3.1'!$A:$A,$A6,'Задача3.1'!$H:$H,E$1,'Задача3.1'!$E:$E,">=9")-COUNTIFS('Задача3.1'!$A:$A,$A6,'Задача3.1'!$H:$H,E$1,'Задача3.1'!$E:$E,"<=6"))/COUNTIFS('Задача3.1'!$A:$A,$A6,'Задача3.1'!$H:$H,E$1,'Задача3.1'!$E:$E,">=0"),"") | F6: =IFERROR((COUNTIFS('Задача3.1'!$A:$A,$A6,'Задача3.1'!$H:$H,F$1,'Задача3.1'!$E:$E,">=9")-COUNTIFS('Задача3.1'!$A:$A,$A6,'Задача3.1'!$H:$H,F$1,'Задача3.1'!$E:$E,"<=6"))/COUNTIFS('Задача3.1'!$A:$A,$A6,'Задача3.1'!$H:$H,F$1,'Задача3.1'!$E:$E,">=0"),"") -> 0 | G6: =IFERROR((COUNTIFS('Задача3.1'!$A:$A,$A6,'Задача3.1'!$H:$H,G$1,'Задача3.1'!$E:$E,">=9")-COUNTIFS('Задача3.1'!$A:$A,$A6,'Задача3.1'!$H:$H,G$1,'Задача3.1'!$E:$E,"<=6"))/COUNTIFS('Задача3.1'!$A:$A,$A6,'Задача3.1'!$H:$H,G$1,'Задача3.1'!$E:$E,">=0"),"") -> -0.5 | H6: =IFERROR((COUNTIFS('Задача3.1'!$A:$A,$A6,'Задача3.1'!$H:$H,H$1,'Задача3.1'!$E:$E,">=9")-COUNTIFS('Задача3.1'!$A:$A,$A6,'Задача3.1'!$H:$H,H$1,'Задача3.1'!$E:$E,"<=6"))/COUNTIFS('Задача3.1'!$A:$A,$A6,'Задача3.1'!$H:$H,H$1,'Задача3.1'!$E:$E,">=0"),"") -> -1 | I6: =IFERROR((COUNTIFS('Задача3.1'!$A:$A,$A6,'Задача3.1'!$H:$H,I$1,'Задача3.1'!$E:$E,">=9")-COUNTIFS('Задача3.1'!$A:$A,$A6,'Задача3.1'!$H:$H,I$1,'Задача3.1'!$E:$E,"<=6"))/COUNTIFS('Задача3.1'!$A:$A,$A6,'Задача3.1'!$H:$H,I$1,'Задача3.1'!$E:$E,">=0"),"") -> -0.5 | ... N6: =IFERROR((COUNTIFS('Задача3.1'!$A:$A,$A6,'Задача3.1'!$H:$H,N$1,'Задача3.1'!$E:$E,">=9")-COUNTIFS('Задача3.1'!$A:$A,$A6,'Задача3.1'!$H:$H,N$1,'Задача3.1'!$E:$E,"<=6"))/COUNTIFS('Задача3.1'!$A:$A,$A6,'Задача3.1'!$H:$H,N$1,'Задача3.1'!$E:$E,">=0"),"") -> 0
A7: Орлов Павел Денисович | B7: =IFERROR((COUNTIFS('Задача3.1'!$A:$A,$A7,'Задача3.1'!$H:$H,B$1,'Задача3.1'!$E:$E,">=9")-COUNTIFS('Задача3.1'!$A:$A,$A7,'Задача3.1'!$H:$H,B$1,'Задача3.1'!$E:$E,"<=6"))/COUNTIFS('Задача3.1'!$A:$A,$A7,'Задача3.1'!$H:$H,B$1,'Задача3.1'!$E:$E,">=0"),"") -> -1 | C7: =IFERROR((COUNTIFS('Задача3.1'!$A:$A,$A7,'Задача3.1'!$H:$H,C$1,'Задача3.1'!$E:$E,">=9")-COUNTIFS('Задача3.1'!$A:$A,$A7,'Задача3.1'!$H:$H,C$1,'Задача3.1'!$E:$E,"<=6"))/COUNTIFS('Задача3.1'!$A:$A,$A7,'Задача3.1'!$H:$H,C$1,'Задача3.1'!$E:$E,">=0"),"") | D7: =IFERROR((COUNTIFS('Задача3.1'!$A:$A,$A7,'Задача3.1'!$H:$H,D$1,'Задача3.1'!$E:$E,">=9")-COUNTIFS('Задача3.1'!$A:$A,$A7,'Задача3.1'!$H:$H,D$1,'Задача3.1'!$E:$E,"<=6"))/COUNTIFS('Задача3.1'!$A:$A,$A7,'Задача3.1'!$H:$H,D$1,'Задача3.1'!$E:$E,">=0"),"") -> -1 | E7: =IFERROR((COUNTIFS('Задача3.1'!$A:$A,$A7,'Задача3.1'!$H:$H,E$1,'Задача3.1'!$E:$E,">=9")-COUNTIFS('Задача3.1'!$A:$A,$A7,'Задача3.1'!$H:$H,E$1,'Задача3.1'!$E:$E,"<=6"))/COUNTIFS('Задача3.1'!$A:$A,$A7,'Задача3.1'!$H:$H,E$1,'Задача3.1'!$E:$E,">=0"),"") -> -1 | F7: =IFERROR((COUNTIFS('Задача3.1'!$A:$A,$A7,'Задача3.1'!$H:$H,F$1,'Задача3.1'!$E:$E,">=9")-COUNTIFS('Задача3.1'!$A:$A,$A7,'Задача3.1'!$H:$H,F$1,'Задача3.1'!$E:$E,"<=6"))/COUNTIFS('Задача3.1'!$A:$A,$A7,'Задача3.1'!$H:$H,F$1,'Задача3.1'!$E:$E,">=0"),"") -> 0 | G7: =IFERROR((COUNTIFS('Задача3.1'!$A:$A,$A7,'Задача3.1'!$H:$H,G$1,'Задача3.1'!$E:$E,">=9")-COUNTIFS('Задача3.1'!$A:$A,$A7,'Задача3.1'!$H:$H,G$1,'Задача3.1'!$E:$E,"<=6"))/COUNTIFS('Задача3.1'!$A:$A,$A7,'Задача3.1'!$H:$H,G$1,'Задача3.1'!$E:$E,">=0"),"") | H7: =IFERROR((COUNTIFS('Задача3.1'!$A:$A,$A7,'Задача3.1'!$H:$H,H$1,'Задача3.1'!$E:$E,">=9")-COUNTIFS('Задача3.1'!$A:$A,$A7,'Задача3.1'!$H:$H,H$1,'Задача3.1'!$E:$E,"<=6"))/COUNTIFS('Задача3.1'!$A:$A,$A7,'Задача3.1'!$H:$H,H$1,'Задача3.1'!$E:$E,">=0"),"") -> -0.66666667 | I7: =IFERROR((COUNTIFS('Задача3.1'!$A:$A,$A7,'Задача3.1'!$H:$H,I$1,'Задача3.1'!$E:$E,">=9")-COUNTIFS('Задача3.1'!$A:$A,$A7,'Задача3.1'!$H:$H,I$1,'Задача3.1'!$E:$E,"<=6"))/COUNTIFS('Задача3.1'!$A:$A,$A7,'Задача3.1'!$H:$H,I$1,'Задача3.1'!$E:$E,">=0"),"") -> -0.33333333 | ... N7: =IFERROR((COUNTIFS('Задача3.1'!$A:$A,$A7,'Задача3.1'!$H:$H,N$1,'Задача3.1'!$E:$E,">=9")-COUNTIFS('Задача3.1'!$A:$A,$A7,'Задача3.1'!$H:$H,N$1,'Задача3.1'!$E:$E,"<=6"))/COUNTIFS('Задача3.1'!$A:$A,$A7,'Задача3.1'!$H:$H,N$1,'Задача3.1'!$E:$E,">=0"),"") -> 1
A8: Петров Владимир Кириллович | B8: =IFERROR((COUNTIFS('Задача3.1'!$A:$A,$A8,'Задача3.1'!$H:$H,B$1,'Задача3.1'!$E:$E,">=9")-COUNTIFS('Задача3.1'!$A:$A,$A8,'Задача3.1'!$H:$H,B$1,'Задача3.1'!$E:$E,"<=6"))/COUNTIFS('Задача3.1'!$A:$A,$A8,'Задача3.1'!$H:$H,B$1,'Задача3.1'!$E:$E,">=0"),"") | C8: =IFERROR((COUNTIFS('Задача3.1'!$A:$A,$A8,'Задача3.1'!$H:$H,C$1,'Задача3.1'!$E:$E,">=9")-COUNTIFS('Задача3.1'!$A:$A,$A8,'Задача3.1'!$H:$H,C$1,'Задача3.1'!$E:$E,"<=6"))/COUNTIFS('Задача3.1'!$A:$A,$A8,'Задача3.1'!$H:$H,C$1,'Задача3.1'!$E:$E,">=0"),"") | D8: =IFERROR((COUNTIFS('Задача3.1'!$A:$A,$A8,'Задача3.1'!$H:$H,D$1,'Задача3.1'!$E:$E,">=9")-COUNTIFS('Задача3.1'!$A:$A,$A8,'Задача3.1'!$H:$H,D$1,'Задача3.1'!$E:$E,"<=6"))/COUNTIFS('Задача3.1'!$A:$A,$A8,'Задача3.1'!$H:$H,D$1,'Задача3.1'!$E:$E,">=0"),"") -> -1 | E8: =IFERROR((COUNTIFS('Задача3.1'!$A:$A,$A8,'Задача3.1'!$H:$H,E$1,'Задача3.1'!$E:$E,">=9")-COUNTIFS('Задача3.1'!$A:$A,$A8,'Задача3.1'!$H:$H,E$1,'Задача3.1'!$E:$E,"<=6"))/COUNTIFS('Задача3.1'!$A:$A,$A8,'Задача3.1'!$H:$H,E$1,'Задача3.1'!$E:$E,">=0"),"") | F8: =IFERROR((COUNTIFS('Задача3.1'!$A:$A,$A8,'Задача3.1'!$H:$H,F$1,'Задача3.1'!$E:$E,">=9")-COUNTIFS('Задача3.1'!$A:$A,$A8,'Задача3.1'!$H:$H,F$1,'Задача3.1'!$E:$E,"<=6"))/COUNTIFS('Задача3.1'!$A:$A,$A8,'Задача3.1'!$H:$H,F$1,'Задача3.1'!$E:$E,">=0"),"") -> -1 | G8: =IFERROR((COUNTIFS('Задача3.1'!$A:$A,$A8,'Задача3.1'!$H:$H,G$1,'Задача3.1'!$E:$E,">=9")-COUNTIFS('Задача3.1'!$A:$A,$A8,'Задача3.1'!$H:$H,G$1,'Задача3.1'!$E:$E,"<=6"))/COUNTIFS('Задача3.1'!$A:$A,$A8,'Задача3.1'!$H:$H,G$1,'Задача3.1'!$E:$E,">=0"),"") | H8: =IFERROR((COUNTIFS('Задача3.1'!$A:$A,$A8,'Задача3.1'!$H:$H,H$1,'Задача3.1'!$E:$E,">=9")-COUNTIFS('Задача3.1'!$A:$A,$A8,'Задача3.1'!$H:$H,H$1,'Задача3.1'!$E:$E,"<=6"))/COUNTIFS('Задача3.1'!$A:$A,$A8,'Задача3.1'!$H:$H,H$1,'Задача3.1'!$E:$E,">=0"),"") -> -1 | I8: =IFERROR((COUNTIFS('Задача3.1'!$A:$A,$A8,'Задача3.1'!$H:$H,I$1,'Задача3.1'!$E:$E,">=9")-COUNTIFS('Задача3.1'!$A:$A,$A8,'Задача3.1'!$H:$H,I$1,'Задача3.1'!$E:$E,"<=6"))/COUNTIFS('Задача3.1'!$A:$A,$A8,'Задача3.1'!$H:$H,I$1,'Задача3.1'!$E:$E,">=0"),"") | ... N8: =IFERROR((COUNTIFS('Задача3.1'!$A:$A,$A8,'Задача3.1'!$H:$H,N$1,'Задача3.1'!$E:$E,">=9")-COUNTIFS('Задача3.1'!$A:$A,$A8,'Задача3.1'!$H:$H,N$1,'Задача3.1'!$E:$E,"<=6"))/COUNTIFS('Задача3.1'!$A:$A,$A8,'Задача3.1'!$H:$H,N$1,'Задача3.1'!$E:$E,">=0"),"") -> 0
A9: Семенова Ирина Валерьевна | B9: =IFERROR((COUNTIFS('Задача3.1'!$A:$A,$A9,'Задача3.1'!$H:$H,B$1,'Задача3.1'!$E:$E,">=9")-COUNTIFS('Задача3.1'!$A:$A,$A9,'Задача3.1'!$H:$H,B$1,'Задача3.1'!$E:$E,"<=6"))/COUNTIFS('Задача3.1'!$A:$A,$A9,'Задача3.1'!$H:$H,B$1,'Задача3.1'!$E:$E,">=0"),"") -> -1 | C9: =IFERROR((COUNTIFS('Задача3.1'!$A:$A,$A9,'Задача3.1'!$H:$H,C$1,'Задача3.1'!$E:$E,">=9")-COUNTIFS('Задача3.1'!$A:$A,$A9,'Задача3.1'!$H:$H,C$1,'Задача3.1'!$E:$E,"<=6"))/COUNTIFS('Задача3.1'!$A:$A,$A9,'Задача3.1'!$H:$H,C$1,'Задача3.1'!$E:$E,">=0"),"") -> 0 | D9: =IFERROR((COUNTIFS('Задача3.1'!$A:$A,$A9,'Задача3.1'!$H:$H,D$1,'Задача3.1'!$E:$E,">=9")-COUNTIFS('Задача3.1'!$A:$A,$A9,'Задача3.1'!$H:$H,D$1,'Задача3.1'!$E:$E,"<=6"))/COUNTIFS('Задача3.1'!$A:$A,$A9,'Задача3.1'!$H:$H,D$1,'Задача3.1'!$E:$E,">=0"),"") -> -1 | E9: =IFERROR((COUNTIFS('Задача3.1'!$A:$A,$A9,'Задача3.1'!$H:$H,E$1,'Задача3.1'!$E:$E,">=9")-COUNTIFS('Задача3.1'!$A:$A,$A9,'Задача3.1'!$H:$H,E$1,'Задача3.1'!$E:$E,"<=6"))/COUNTIFS('Задача3.1'!$A:$A,$A9,'Задача3.1'!$H:$H,E$1,'Задача3.1'!$E:$E,">=0"),"") -> 1 | F9: =IFERROR((COUNTIFS('Задача3.1'!$A:$A,$A9,'Задача3.1'!$H:$H,F$1,'Задача3.1'!$E:$E,">=9")-COUNTIFS('Задача3.1'!$A:$A,$A9,'Задача3.1'!$H:$H,F$1,'Задача3.1'!$E:$E,"<=6"))/COUNTIFS('Задача3.1'!$A:$A,$A9,'Задача3.1'!$H:$H,F$1,'Задача3.1'!$E:$E,">=0"),"") -> -0.66666667 | G9: =IFERROR((COUNTIFS('Задача3.1'!$A:$A,$A9,'Задача3.1'!$H:$H,G$1,'Задача3.1'!$E:$E,">=9")-COUNTIFS('Задача3.1'!$A:$A,$A9,'Задача3.1'!$H:$H,G$1,'Задача3.1'!$E:$E,"<=6"))/COUNTIFS('Задача3.1'!$A:$A,$A9,'Задача3.1'!$H:$H,G$1,'Задача3.1'!$E:$E,">=0"),"") | H9: =IFERROR((COUNTIFS('Задача3.1'!$A:$A,$A9,'Задача3.1'!$H:$H,H$1,'Задача3.1'!$E:$E,">=9")-COUNTIFS('Задача3.1'!$A:$A,$A9,'Задача3.1'!$H:$H,H$1,'Задача3.1'!$E:$E,"<=6"))/COUNTIFS('Задача3.1'!$A:$A,$A9,'Задача3.1'!$H:$H,H$1,'Задача3.1'!$E:$E,">=0"),"") -> -0.5 | I9: =IFERROR((COUNTIFS('Задача3.1'!$A:$A,$A9,'Задача3.1'!$H:$H,I$1,'Задача3.1'!$E:$E,">=9")-COUNTIFS('Задача3.1'!$A:$A,$A9,'Задача3.1'!$H:$H,I$1,'Задача3.1'!$E:$E,"<=6"))/COUNTIFS('Задача3.1'!$A:$A,$A9,'Задача3.1'!$H:$H,I$1,'Задача3.1'!$E:$E,">=0"),"") -> -0.33333333 | ... N9: =IFERROR((COUNTIFS('Задача3.1'!$A:$A,$A9,'Задача3.1'!$H:$H,N$1,'Задача3.1'!$E:$E,">=9")-COUNTIFS('Задача3.1'!$A:$A,$A9,'Задача3.1'!$H:$H,N$1,'Задача3.1'!$E:$E,"<=6"))/COUNTIFS('Задача3.1'!$A:$A,$A9,'Задача3.1'!$H:$H,N$1,'Задача3.1'!$E:$E,">=0"),"")
A10: Сидорова Елена Васильевна | B10: =IFERROR((COUNTIFS('Задача3.1'!$A:$A,$A10,'Задача3.1'!$H:$H,B$1,'Задача3.1'!$E:$E,">=9")-COUNTIFS('Задача3.1'!$A:$A,$A10,'Задача3.1'!$H:$H,B$1,'Задача3.1'!$E:$E,"<=6"))/COUNTIFS('Задача3.1'!$A:$A,$A10,'Задача3.1'!$H:$H,B$1,'Задача3.1'!$E:$E,">=0"),"") -> 1 | C10: =IFERROR((COUNTIFS('Задача3.1'!$A:$A,$A10,'Задача3.1'!$H:$H,C$1,'Задача3.1'!$E:$E,">=9")-COUNTIFS('Задача3.1'!$A:$A,$A10,'Задача3.1'!$H:$H,C$1,'Задача3.1'!$E:$E,"<=6"))/COUNTIFS('Задача3.1'!$A:$A,$A10,'Задача3.1'!$H:$H,C$1,'Задача3.1'!$E:$E,">=0"),"") -> 0 | D10: =IFERROR((COUNTIFS('Задача3.1'!$A:$A,$A10,'Задача3.1'!$H:$H,D$1,'Задача3.1'!$E:$E,">=9")-COUNTIFS('Задача3.1'!$A:$A,$A10,'Задача3.1'!$H:$H,D$1,'Задача3.1'!$E:$E,"<=6"))/COUNTIFS('Задача3.1'!$A:$A,$A10,'Задача3.1'!$H:$H,D$1,'Задача3.1'!$E:$E,">=0"),"") -> -0.33333333 | E10: =IFERROR((COUNTIFS('Задача3.1'!$A:$A,$A10,'Задача3.1'!$H:$H,E$1,'Задача3.1'!$E:$E,">=9")-COUNTIFS('Задача3.1'!$A:$A,$A10,'Задача3.1'!$H:$H,E$1,'Задача3.1'!$E:$E,"<=6"))/COUNTIFS('Задача3.1'!$A:$A,$A10,'Задача3.1'!$H:$H,E$1,'Задача3.1'!$E:$E,">=0"),"") -> 0 | F10: =IFERROR((COUNTIFS('Задача3.1'!$A:$A,$A10,'Задача3.1'!$H:$H,F$1,'Задача3.1'!$E:$E,">=9")-COUNTIFS('Задача3.1'!$A:$A,$A10,'Задача3.1'!$H:$H,F$1,'Задача3.1'!$E:$E,"<=6"))/COUNTIFS('Задача3.1'!$A:$A,$A10,'Задача3.1'!$H:$H,F$1,'Задача3.1'!$E:$E,">=0"),"") -> -0.5 | G10: =IFERROR((COUNTIFS('Задача3.1'!$A:$A,$A10,'Задача3.1'!$H:$H,G$1,'Задача3.1'!$E:$E,">=9")-COUNTIFS('Задача3.1'!$A:$A,$A10,'Задача3.1'!$H:$H,G$1,'Задача3.1'!$E:$E,"<=6"))/COUNTIFS('Задача3.1'!$A:$A,$A10,'Задача3.1'!$H:$H,G$1,'Задача3.1'!$E:$E,">=0"),"") | H10: =IFERROR((COUNTIFS('Задача3.1'!$A:$A,$A10,'Задача3.1'!$H:$H,H$1,'Задача3.1'!$E:$E,">=9")-COUNTIFS('Задача3.1'!$A:$A,$A10,'Задача3.1'!$H:$H,H$1,'Задача3.1'!$E:$E,"<=6"))/COUNTIFS('Задача3.1'!$A:$A,$A10,'Задача3.1'!$H:$H,H$1,'Задача3.1'!$E:$E,">=0"),"") -> 0 | I10: =IFERROR((COUNTIFS('Задача3.1'!$A:$A,$A10,'Задача3.1'!$H:$H,I$1,'Задача3.1'!$E:$E,">=9")-COUNTIFS('Задача3.1'!$A:$A,$A10,'Задача3.1'!$H:$H,I$1,'Задача3.1'!$E:$E,"<=6"))/COUNTIFS('Задача3.1'!$A:$A,$A10,'Задача3.1'!$H:$H,I$1,'Задача3.1'!$E:$E,">=0"),"") -> -1 | ... N10: =IFERROR((COUNTIFS('Задача3.1'!$A:$A,$A10,'Задача3.1'!$H:$H,N$1,'Задача3.1'!$E:$E,">=9")-COUNTIFS('Задача3.1'!$A:$A,$A10,'Задача3.1'!$H:$H,N$1,'Задача3.1'!$E:$E,"<=6"))/COUNTIFS('Задача3.1'!$A:$A,$A10,'Задача3.1'!$H:$H,N$1,'Задача3.1'!$E:$E,">=0"),"") -> 0
